[2021-04-27 04:02:43,443: ERROR/MainProcess] consumer: Cannot connect to amqp://guest:**@127.0.0.1:5672//: [Errno 111] Connection refused.
Trying again in 2.00 seconds... (1/100)

[2021-04-27 04:02:45,244: INFO/Beat] beat: Starting...
[2021-04-27 04:02:45,461: ERROR/MainProcess] consumer: Cannot connect to amqp://guest:**@127.0.0.1:5672//: [Errno 111] Connection refused.
Trying again in 4.00 seconds... (2/100)

[2021-04-27 04:02:49,479: ERROR/MainProcess] consumer: Cannot connect to amqp://guest:**@127.0.0.1:5672//: [Errno 111] Connection refused.
Trying again in 6.00 seconds... (3/100)

[2021-04-27 04:02:55,512: ERROR/MainProcess] consumer: Cannot connect to amqp://guest:**@127.0.0.1:5672//: [Errno 111] Connection refused.
Trying again in 8.00 seconds... (4/100)

[2021-04-27 04:03:03,528: ERROR/MainProcess] consumer: Cannot connect to amqp://guest:**@127.0.0.1:5672//: [Errno 111] Connection refused.
Trying again in 10.00 seconds... (5/100)

[2021-04-27 04:03:13,562: ERROR/MainProcess] consumer: Cannot connect to amqp://guest:**@127.0.0.1:5672//: [Errno 111] Connection refused.
Trying again in 12.00 seconds... (6/100)

[2021-04-27 04:03:25,610: ERROR/MainProcess] consumer: Cannot connect to amqp://guest:**@127.0.0.1:5672//: [Errno 111] Connection refused.
Trying again in 14.00 seconds... (7/100)

[2021-04-27 04:03:39,659: ERROR/MainProcess] consumer: Cannot connect to amqp://guest:**@127.0.0.1:5672//: [Errno 111] Connection refused.
Trying again in 16.00 seconds... (8/100)

[2021-04-27 04:03:55,716: ERROR/MainProcess] consumer: Cannot connect to amqp://guest:**@127.0.0.1:5672//: [Errno 111] Connection refused.
Trying again in 18.00 seconds... (9/100)

[2021-04-27 04:04:13,757: ERROR/MainProcess] consumer: Cannot connect to amqp://guest:**@127.0.0.1:5672//: [Errno 111] Connection refused.
Trying again in 20.00 seconds... (10/100)

[2021-04-27 04:04:33,785: ERROR/MainProcess] consumer: Cannot connect to amqp://guest:**@127.0.0.1:5672//: [Errno 111] Connection refused.
Trying again in 22.00 seconds... (11/100)

[2021-04-27 04:04:55,838: ERROR/MainProcess] consumer: Cannot connect to amqp://guest:**@127.0.0.1:5672//: [Errno 111] Connection refused.
Trying again in 24.00 seconds... (12/100)

[2021-04-27 04:05:01,371: INFO/MainProcess] beat: Shutting down...
[2021-04-27 04:06:19,452: ERROR/MainProcess] consumer: Cannot connect to amqp://guest:**@127.0.0.1:5672//: [Errno 111] Connection refused.
Trying again in 2.00 seconds... (1/100)

[2021-04-27 04:06:21,462: ERROR/MainProcess] consumer: Cannot connect to amqp://guest:**@127.0.0.1:5672//: [Errno 111] Connection refused.
Trying again in 4.00 seconds... (2/100)

[2021-04-27 04:06:21,596: INFO/Beat] beat: Starting...
[2021-04-27 04:06:25,485: ERROR/MainProcess] consumer: Cannot connect to amqp://guest:**@127.0.0.1:5672//: [Errno 111] Connection refused.
Trying again in 6.00 seconds... (3/100)

[2021-04-27 04:06:31,494: ERROR/MainProcess] consumer: Cannot connect to amqp://guest:**@127.0.0.1:5672//: [Errno 111] Connection refused.
Trying again in 8.00 seconds... (4/100)

[2021-04-27 04:06:39,537: ERROR/MainProcess] consumer: Cannot connect to amqp://guest:**@127.0.0.1:5672//: [Errno 111] Connection refused.
Trying again in 10.00 seconds... (5/100)

[2021-04-27 04:06:42,415: INFO/MainProcess] beat: Shutting down...
[2021-04-27 04:07:24,742: INFO/MainProcess] Connected to redis://redis:6379//
[2021-04-27 04:07:24,774: INFO/MainProcess] mingle: searching for neighbors
[2021-04-27 04:07:25,807: INFO/MainProcess] mingle: all alone
[2021-04-27 04:07:25,830: WARNING/MainProcess] /usr/local/lib/python3.7/site-packages/celery/fixups/django.py:204: UserWarning: Using settings.DEBUG leads to a memory
            leak, never use this setting in production environments!
  leak, never use this setting in production environments!''')

[2021-04-27 04:07:25,832: INFO/MainProcess] celery@dc774e56226d ready.
[2021-04-27 04:07:26,638: INFO/Beat] beat: Starting...
[2021-04-27 04:10:22,792: INFO/MainProcess] beat: Shutting down...
[2021-04-27 04:10:33,661: ERROR/MainProcess] consumer: Cannot connect to amqp://guest:**@127.0.0.1:5672//: [Errno 111] Connection refused.
Trying again in 2.00 seconds... (1/100)

[2021-04-27 04:10:35,672: ERROR/MainProcess] consumer: Cannot connect to amqp://guest:**@127.0.0.1:5672//: [Errno 111] Connection refused.
Trying again in 4.00 seconds... (2/100)

[2021-04-27 04:10:35,822: INFO/Beat] beat: Starting...
[2021-04-27 04:10:35,840: ERROR/Beat] Removing corrupted schedule file 'celerybeat-schedule': error(11, 'Resource temporarily unavailable')
Traceback (most recent call last):
  File "/usr/local/lib/python3.7/site-packages/kombu/utils/objects.py", line 41, in __get__
    return obj.__dict__[self.__name__]
KeyError: 'scheduler'

During handling of the above exception, another exception occurred:

Traceback (most recent call last):
  File "/usr/local/lib/python3.7/site-packages/celery/beat.py", line 515, in setup_schedule
    self._store = self._open_schedule()
  File "/usr/local/lib/python3.7/site-packages/celery/beat.py", line 505, in _open_schedule
    return self.persistence.open(self.schedule_filename, writeback=True)
  File "/usr/local/lib/python3.7/shelve.py", line 243, in open
    return DbfilenameShelf(filename, flag, protocol, writeback)
  File "/usr/local/lib/python3.7/shelve.py", line 227, in __init__
    Shelf.__init__(self, dbm.open(filename, flag), protocol, writeback)
  File "/usr/local/lib/python3.7/dbm/__init__.py", line 94, in open
    return mod.open(file, flag, mode)
_gdbm.error: [Errno 11] Resource temporarily unavailable
[2021-04-27 04:10:39,691: ERROR/MainProcess] consumer: Cannot connect to amqp://guest:**@127.0.0.1:5672//: [Errno 111] Connection refused.
Trying again in 6.00 seconds... (3/100)

[2021-04-27 04:10:45,717: ERROR/MainProcess] consumer: Cannot connect to amqp://guest:**@127.0.0.1:5672//: [Errno 111] Connection refused.
Trying again in 8.00 seconds... (4/100)

[2021-04-27 04:10:53,744: ERROR/MainProcess] consumer: Cannot connect to amqp://guest:**@127.0.0.1:5672//: [Errno 111] Connection refused.
Trying again in 10.00 seconds... (5/100)

[2021-04-27 04:11:03,748: ERROR/MainProcess] consumer: Cannot connect to amqp://guest:**@127.0.0.1:5672//: [Errno 111] Connection refused.
Trying again in 12.00 seconds... (6/100)

[2021-04-27 04:11:15,785: ERROR/MainProcess] consumer: Cannot connect to amqp://guest:**@127.0.0.1:5672//: [Errno 111] Connection refused.
Trying again in 14.00 seconds... (7/100)

[2021-04-27 04:11:29,818: ERROR/MainProcess] consumer: Cannot connect to amqp://guest:**@127.0.0.1:5672//: [Errno 111] Connection refused.
Trying again in 16.00 seconds... (8/100)

[2021-04-27 04:11:36,968: INFO/MainProcess] beat: Shutting down...
[2021-04-27 04:11:57,470: ERROR/MainProcess] consumer: Cannot connect to amqp://guest:**@127.0.0.1:5672//: [Errno 111] Connection refused.
Trying again in 2.00 seconds... (1/100)

[2021-04-27 04:11:59,491: ERROR/MainProcess] consumer: Cannot connect to amqp://guest:**@127.0.0.1:5672//: [Errno 111] Connection refused.
Trying again in 4.00 seconds... (2/100)

[2021-04-27 04:11:59,634: INFO/Beat] beat: Starting...
[2021-04-27 04:11:59,659: ERROR/Beat] Removing corrupted schedule file 'celerybeat-schedule': error(11, 'Resource temporarily unavailable')
Traceback (most recent call last):
  File "/usr/local/lib/python3.7/site-packages/kombu/utils/objects.py", line 41, in __get__
    return obj.__dict__[self.__name__]
KeyError: 'scheduler'

During handling of the above exception, another exception occurred:

Traceback (most recent call last):
  File "/usr/local/lib/python3.7/site-packages/celery/beat.py", line 515, in setup_schedule
    self._store = self._open_schedule()
  File "/usr/local/lib/python3.7/site-packages/celery/beat.py", line 505, in _open_schedule
    return self.persistence.open(self.schedule_filename, writeback=True)
  File "/usr/local/lib/python3.7/shelve.py", line 243, in open
    return DbfilenameShelf(filename, flag, protocol, writeback)
  File "/usr/local/lib/python3.7/shelve.py", line 227, in __init__
    Shelf.__init__(self, dbm.open(filename, flag), protocol, writeback)
  File "/usr/local/lib/python3.7/dbm/__init__.py", line 94, in open
    return mod.open(file, flag, mode)
_gdbm.error: [Errno 11] Resource temporarily unavailable
[2021-04-27 04:12:03,527: ERROR/MainProcess] consumer: Cannot connect to amqp://guest:**@127.0.0.1:5672//: [Errno 111] Connection refused.
Trying again in 6.00 seconds... (3/100)

[2021-04-27 04:12:09,557: ERROR/MainProcess] consumer: Cannot connect to amqp://guest:**@127.0.0.1:5672//: [Errno 111] Connection refused.
Trying again in 8.00 seconds... (4/100)

[2021-04-27 04:12:17,585: ERROR/MainProcess] consumer: Cannot connect to amqp://guest:**@127.0.0.1:5672//: [Errno 111] Connection refused.
Trying again in 10.00 seconds... (5/100)

[2021-04-27 04:12:27,608: ERROR/MainProcess] consumer: Cannot connect to amqp://guest:**@127.0.0.1:5672//: [Errno 111] Connection refused.
Trying again in 12.00 seconds... (6/100)

[2021-04-27 04:12:39,653: ERROR/MainProcess] consumer: Cannot connect to amqp://guest:**@127.0.0.1:5672//: [Errno 111] Connection refused.
Trying again in 14.00 seconds... (7/100)

[2021-04-27 04:12:53,695: ERROR/MainProcess] consumer: Cannot connect to amqp://guest:**@127.0.0.1:5672//: [Errno 111] Connection refused.
Trying again in 16.00 seconds... (8/100)

[2021-04-27 04:13:09,726: ERROR/MainProcess] consumer: Cannot connect to amqp://guest:**@127.0.0.1:5672//: [Errno 111] Connection refused.
Trying again in 18.00 seconds... (9/100)

[2021-04-27 04:13:12,707: INFO/MainProcess] beat: Shutting down...
[2021-04-27 04:23:54,663: ERROR/MainProcess] consumer: Cannot connect to amqp://guest:**@127.0.0.1:5672//: [Errno 111] Connection refused.
Trying again in 2.00 seconds... (1/100)

[2021-04-27 04:23:56,657: ERROR/MainProcess] consumer: Cannot connect to amqp://guest:**@127.0.0.1:5672//: [Errno 111] Connection refused.
Trying again in 4.00 seconds... (2/100)

[2021-04-27 04:23:56,747: INFO/Beat] beat: Starting...
[2021-04-27 04:23:56,771: ERROR/Beat] Removing corrupted schedule file 'celerybeat-schedule': error(11, 'Resource temporarily unavailable')
Traceback (most recent call last):
  File "/usr/local/lib/python3.7/site-packages/kombu/utils/objects.py", line 41, in __get__
    return obj.__dict__[self.__name__]
KeyError: 'scheduler'

During handling of the above exception, another exception occurred:

Traceback (most recent call last):
  File "/usr/local/lib/python3.7/site-packages/celery/beat.py", line 515, in setup_schedule
    self._store = self._open_schedule()
  File "/usr/local/lib/python3.7/site-packages/celery/beat.py", line 505, in _open_schedule
    return self.persistence.open(self.schedule_filename, writeback=True)
  File "/usr/local/lib/python3.7/shelve.py", line 243, in open
    return DbfilenameShelf(filename, flag, protocol, writeback)
  File "/usr/local/lib/python3.7/shelve.py", line 227, in __init__
    Shelf.__init__(self, dbm.open(filename, flag), protocol, writeback)
  File "/usr/local/lib/python3.7/dbm/__init__.py", line 94, in open
    return mod.open(file, flag, mode)
_gdbm.error: [Errno 11] Resource temporarily unavailable
[2021-04-27 04:24:00,679: ERROR/MainProcess] consumer: Cannot connect to amqp://guest:**@127.0.0.1:5672//: [Errno 111] Connection refused.
Trying again in 6.00 seconds... (3/100)

[2021-04-27 04:24:06,704: ERROR/MainProcess] consumer: Cannot connect to amqp://guest:**@127.0.0.1:5672//: [Errno 111] Connection refused.
Trying again in 8.00 seconds... (4/100)

[2021-04-27 04:24:08,382: INFO/MainProcess] beat: Shutting down...
[2021-04-27 04:35:57,234: ERROR/MainProcess] consumer: Cannot connect to amqp://guest:**@127.0.0.1:5672//: [Errno 111] Connection refused.
Trying again in 2.00 seconds... (1/100)

[2021-04-27 04:35:59,068: INFO/Beat] beat: Starting...
[2021-04-27 04:35:59,085: ERROR/Beat] Removing corrupted schedule file 'celerybeat-schedule': error(11, 'Resource temporarily unavailable')
Traceback (most recent call last):
  File "/usr/local/lib/python3.7/site-packages/kombu/utils/objects.py", line 41, in __get__
    return obj.__dict__[self.__name__]
KeyError: 'scheduler'

During handling of the above exception, another exception occurred:

Traceback (most recent call last):
  File "/usr/local/lib/python3.7/site-packages/celery/beat.py", line 515, in setup_schedule
    self._store = self._open_schedule()
  File "/usr/local/lib/python3.7/site-packages/celery/beat.py", line 505, in _open_schedule
    return self.persistence.open(self.schedule_filename, writeback=True)
  File "/usr/local/lib/python3.7/shelve.py", line 243, in open
    return DbfilenameShelf(filename, flag, protocol, writeback)
  File "/usr/local/lib/python3.7/shelve.py", line 227, in __init__
    Shelf.__init__(self, dbm.open(filename, flag), protocol, writeback)
  File "/usr/local/lib/python3.7/dbm/__init__.py", line 94, in open
    return mod.open(file, flag, mode)
_gdbm.error: [Errno 11] Resource temporarily unavailable
[2021-04-27 04:35:59,248: ERROR/MainProcess] consumer: Cannot connect to amqp://guest:**@127.0.0.1:5672//: [Errno 111] Connection refused.
Trying again in 4.00 seconds... (2/100)

[2021-04-27 04:36:03,268: ERROR/MainProcess] consumer: Cannot connect to amqp://guest:**@127.0.0.1:5672//: [Errno 111] Connection refused.
Trying again in 6.00 seconds... (3/100)

[2021-04-27 04:36:09,290: ERROR/MainProcess] consumer: Cannot connect to amqp://guest:**@127.0.0.1:5672//: [Errno 111] Connection refused.
Trying again in 8.00 seconds... (4/100)

[2021-04-27 04:36:17,329: ERROR/MainProcess] consumer: Cannot connect to amqp://guest:**@127.0.0.1:5672//: [Errno 111] Connection refused.
Trying again in 10.00 seconds... (5/100)

[2021-04-27 04:36:27,344: ERROR/MainProcess] consumer: Cannot connect to amqp://guest:**@127.0.0.1:5672//: [Errno 111] Connection refused.
Trying again in 12.00 seconds... (6/100)

[2021-04-27 04:36:39,376: ERROR/MainProcess] consumer: Cannot connect to amqp://guest:**@127.0.0.1:5672//: [Errno 111] Connection refused.
Trying again in 14.00 seconds... (7/100)

[2021-04-27 04:36:53,415: ERROR/MainProcess] consumer: Cannot connect to amqp://guest:**@127.0.0.1:5672//: [Errno 111] Connection refused.
Trying again in 16.00 seconds... (8/100)

[2021-04-27 04:37:03,588: INFO/MainProcess] beat: Shutting down...
[2021-04-27 06:00:43,915: ERROR/MainProcess] consumer: Cannot connect to amqp://guest:**@127.0.0.1:5672//: [Errno 111] Connection refused.
Trying again in 2.00 seconds... (1/100)

[2021-04-27 06:00:45,926: ERROR/MainProcess] consumer: Cannot connect to amqp://guest:**@127.0.0.1:5672//: [Errno 111] Connection refused.
Trying again in 4.00 seconds... (2/100)

[2021-04-27 06:00:46,100: INFO/Beat] beat: Starting...
[2021-04-27 06:00:46,120: ERROR/Beat] Removing corrupted schedule file 'celerybeat-schedule': error(11, 'Resource temporarily unavailable')
Traceback (most recent call last):
  File "/usr/local/lib/python3.7/site-packages/kombu/utils/objects.py", line 41, in __get__
    return obj.__dict__[self.__name__]
KeyError: 'scheduler'

During handling of the above exception, another exception occurred:

Traceback (most recent call last):
  File "/usr/local/lib/python3.7/site-packages/celery/beat.py", line 515, in setup_schedule
    self._store = self._open_schedule()
  File "/usr/local/lib/python3.7/site-packages/celery/beat.py", line 505, in _open_schedule
    return self.persistence.open(self.schedule_filename, writeback=True)
  File "/usr/local/lib/python3.7/shelve.py", line 243, in open
    return DbfilenameShelf(filename, flag, protocol, writeback)
  File "/usr/local/lib/python3.7/shelve.py", line 227, in __init__
    Shelf.__init__(self, dbm.open(filename, flag), protocol, writeback)
  File "/usr/local/lib/python3.7/dbm/__init__.py", line 94, in open
    return mod.open(file, flag, mode)
_gdbm.error: [Errno 11] Resource temporarily unavailable
[2021-04-27 06:00:49,947: ERROR/MainProcess] consumer: Cannot connect to amqp://guest:**@127.0.0.1:5672//: [Errno 111] Connection refused.
Trying again in 6.00 seconds... (3/100)

[2021-04-27 06:00:55,980: ERROR/MainProcess] consumer: Cannot connect to amqp://guest:**@127.0.0.1:5672//: [Errno 111] Connection refused.
Trying again in 8.00 seconds... (4/100)

[2021-04-27 06:01:03,982: ERROR/MainProcess] consumer: Cannot connect to amqp://guest:**@127.0.0.1:5672//: [Errno 111] Connection refused.
Trying again in 10.00 seconds... (5/100)

[2021-04-27 06:01:12,102: INFO/MainProcess] beat: Shutting down...
[2021-04-27 06:04:19,401: ERROR/MainProcess] consumer: Cannot connect to amqp://guest:**@127.0.0.1:5672//: [Errno 111] Connection refused.
Trying again in 2.00 seconds... (1/100)

[2021-04-27 06:04:21,414: ERROR/MainProcess] consumer: Cannot connect to amqp://guest:**@127.0.0.1:5672//: [Errno 111] Connection refused.
Trying again in 4.00 seconds... (2/100)

[2021-04-27 06:04:23,806: INFO/Beat] beat: Starting...
[2021-04-27 06:04:23,841: ERROR/Beat] Removing corrupted schedule file 'celerybeat-schedule': error(11, 'Resource temporarily unavailable')
Traceback (most recent call last):
  File "/usr/local/lib/python3.7/site-packages/kombu/utils/objects.py", line 41, in __get__
    return obj.__dict__[self.__name__]
KeyError: 'scheduler'

During handling of the above exception, another exception occurred:

Traceback (most recent call last):
  File "/usr/local/lib/python3.7/site-packages/celery/beat.py", line 515, in setup_schedule
    self._store = self._open_schedule()
  File "/usr/local/lib/python3.7/site-packages/celery/beat.py", line 505, in _open_schedule
    return self.persistence.open(self.schedule_filename, writeback=True)
  File "/usr/local/lib/python3.7/shelve.py", line 243, in open
    return DbfilenameShelf(filename, flag, protocol, writeback)
  File "/usr/local/lib/python3.7/shelve.py", line 227, in __init__
    Shelf.__init__(self, dbm.open(filename, flag), protocol, writeback)
  File "/usr/local/lib/python3.7/dbm/__init__.py", line 94, in open
    return mod.open(file, flag, mode)
_gdbm.error: [Errno 11] Resource temporarily unavailable
[2021-04-27 06:04:25,435: ERROR/MainProcess] consumer: Cannot connect to amqp://guest:**@127.0.0.1:5672//: [Errno 111] Connection refused.
Trying again in 6.00 seconds... (3/100)

[2021-04-27 06:04:31,426: ERROR/MainProcess] consumer: Cannot connect to amqp://guest:**@127.0.0.1:5672//: [Errno 111] Connection refused.
Trying again in 8.00 seconds... (4/100)

[2021-04-27 06:04:39,442: ERROR/MainProcess] consumer: Cannot connect to amqp://guest:**@127.0.0.1:5672//: [Errno 111] Connection refused.
Trying again in 10.00 seconds... (5/100)

[2021-04-27 06:04:49,467: ERROR/MainProcess] consumer: Cannot connect to amqp://guest:**@127.0.0.1:5672//: [Errno 111] Connection refused.
Trying again in 12.00 seconds... (6/100)

[2021-04-27 06:05:01,461: ERROR/MainProcess] consumer: Cannot connect to amqp://guest:**@127.0.0.1:5672//: [Errno 111] Connection refused.
Trying again in 14.00 seconds... (7/100)

[2021-04-27 06:05:15,495: ERROR/MainProcess] consumer: Cannot connect to amqp://guest:**@127.0.0.1:5672//: [Errno 111] Connection refused.
Trying again in 16.00 seconds... (8/100)

[2021-04-27 06:05:31,487: ERROR/MainProcess] consumer: Cannot connect to amqp://guest:**@127.0.0.1:5672//: [Errno 111] Connection refused.
Trying again in 18.00 seconds... (9/100)

[2021-04-27 06:05:49,582: ERROR/MainProcess] consumer: Cannot connect to amqp://guest:**@127.0.0.1:5672//: [Errno 111] Connection refused.
Trying again in 20.00 seconds... (10/100)

[2021-04-27 06:06:09,598: ERROR/MainProcess] consumer: Cannot connect to amqp://guest:**@127.0.0.1:5672//: [Errno 111] Connection refused.
Trying again in 22.00 seconds... (11/100)

[2021-04-27 06:06:31,617: ERROR/MainProcess] consumer: Cannot connect to amqp://guest:**@127.0.0.1:5672//: [Errno 111] Connection refused.
Trying again in 24.00 seconds... (12/100)

[2021-04-27 06:06:55,707: ERROR/MainProcess] consumer: Cannot connect to amqp://guest:**@127.0.0.1:5672//: [Errno 111] Connection refused.
Trying again in 26.00 seconds... (13/100)

[2021-04-27 06:07:21,773: ERROR/MainProcess] consumer: Cannot connect to amqp://guest:**@127.0.0.1:5672//: [Errno 111] Connection refused.
Trying again in 28.00 seconds... (14/100)

[2021-04-27 06:07:49,814: ERROR/MainProcess] consumer: Cannot connect to amqp://guest:**@127.0.0.1:5672//: [Errno 111] Connection refused.
Trying again in 30.00 seconds... (15/100)

[2021-04-27 06:08:19,857: ERROR/MainProcess] consumer: Cannot connect to amqp://guest:**@127.0.0.1:5672//: [Errno 111] Connection refused.
Trying again in 32.00 seconds... (16/100)

[2021-04-27 06:08:51,912: ERROR/MainProcess] consumer: Cannot connect to amqp://guest:**@127.0.0.1:5672//: [Errno 111] Connection refused.
Trying again in 32.00 seconds... (16/100)

[2021-04-27 06:09:23,986: ERROR/MainProcess] consumer: Cannot connect to amqp://guest:**@127.0.0.1:5672//: [Errno 111] Connection refused.
Trying again in 32.00 seconds... (16/100)

[2021-04-27 06:09:56,060: ERROR/MainProcess] consumer: Cannot connect to amqp://guest:**@127.0.0.1:5672//: [Errno 111] Connection refused.
Trying again in 32.00 seconds... (16/100)

[2021-04-27 06:10:28,128: ERROR/MainProcess] consumer: Cannot connect to amqp://guest:**@127.0.0.1:5672//: [Errno 111] Connection refused.
Trying again in 32.00 seconds... (16/100)

[2021-04-27 06:11:00,181: ERROR/MainProcess] consumer: Cannot connect to amqp://guest:**@127.0.0.1:5672//: [Errno 111] Connection refused.
Trying again in 32.00 seconds... (16/100)

[2021-04-27 06:11:32,262: ERROR/MainProcess] consumer: Cannot connect to amqp://guest:**@127.0.0.1:5672//: [Errno 111] Connection refused.
Trying again in 32.00 seconds... (16/100)

[2021-04-27 06:12:04,355: ERROR/MainProcess] consumer: Cannot connect to amqp://guest:**@127.0.0.1:5672//: [Errno 111] Connection refused.
Trying again in 32.00 seconds... (16/100)

[2021-04-27 06:12:36,449: ERROR/MainProcess] consumer: Cannot connect to amqp://guest:**@127.0.0.1:5672//: [Errno 111] Connection refused.
Trying again in 32.00 seconds... (16/100)

[2021-04-27 06:13:08,530: ERROR/MainProcess] consumer: Cannot connect to amqp://guest:**@127.0.0.1:5672//: [Errno 111] Connection refused.
Trying again in 32.00 seconds... (16/100)

[2021-04-27 06:13:40,629: ERROR/MainProcess] consumer: Cannot connect to amqp://guest:**@127.0.0.1:5672//: [Errno 111] Connection refused.
Trying again in 32.00 seconds... (16/100)

[2021-04-27 06:14:12,710: ERROR/MainProcess] consumer: Cannot connect to amqp://guest:**@127.0.0.1:5672//: [Errno 111] Connection refused.
Trying again in 32.00 seconds... (16/100)

[2021-04-27 06:14:44,804: ERROR/MainProcess] consumer: Cannot connect to amqp://guest:**@127.0.0.1:5672//: [Errno 111] Connection refused.
Trying again in 32.00 seconds... (16/100)

[2021-04-27 06:15:16,861: ERROR/MainProcess] consumer: Cannot connect to amqp://guest:**@127.0.0.1:5672//: [Errno 111] Connection refused.
Trying again in 32.00 seconds... (16/100)

[2021-04-27 06:15:48,966: ERROR/MainProcess] consumer: Cannot connect to amqp://guest:**@127.0.0.1:5672//: [Errno 111] Connection refused.
Trying again in 32.00 seconds... (16/100)

[2021-04-27 06:16:21,039: ERROR/MainProcess] consumer: Cannot connect to amqp://guest:**@127.0.0.1:5672//: [Errno 111] Connection refused.
Trying again in 32.00 seconds... (16/100)

[2021-04-27 06:16:53,111: ERROR/MainProcess] consumer: Cannot connect to amqp://guest:**@127.0.0.1:5672//: [Errno 111] Connection refused.
Trying again in 32.00 seconds... (16/100)

[2021-04-27 06:17:25,173: ERROR/MainProcess] consumer: Cannot connect to amqp://guest:**@127.0.0.1:5672//: [Errno 111] Connection refused.
Trying again in 32.00 seconds... (16/100)

[2021-04-27 06:17:57,305: ERROR/MainProcess] consumer: Cannot connect to amqp://guest:**@127.0.0.1:5672//: [Errno 111] Connection refused.
Trying again in 32.00 seconds... (16/100)

[2021-04-27 06:18:29,330: ERROR/MainProcess] consumer: Cannot connect to amqp://guest:**@127.0.0.1:5672//: [Errno 111] Connection refused.
Trying again in 32.00 seconds... (16/100)

[2021-04-27 06:18:42,613: INFO/MainProcess] beat: Shutting down...
[2021-04-27 06:21:52,601: ERROR/MainProcess] consumer: Cannot connect to amqp://guest:**@127.0.0.1:5672//: [Errno 111] Connection refused.
Trying again in 2.00 seconds... (1/100)

[2021-04-27 06:21:54,610: ERROR/MainProcess] consumer: Cannot connect to amqp://guest:**@127.0.0.1:5672//: [Errno 111] Connection refused.
Trying again in 4.00 seconds... (2/100)

[2021-04-27 06:21:54,809: INFO/Beat] beat: Starting...
[2021-04-27 06:21:54,829: ERROR/Beat] Removing corrupted schedule file 'celerybeat-schedule': error(11, 'Resource temporarily unavailable')
Traceback (most recent call last):
  File "/usr/local/lib/python3.7/site-packages/kombu/utils/objects.py", line 41, in __get__
    return obj.__dict__[self.__name__]
KeyError: 'scheduler'

During handling of the above exception, another exception occurred:

Traceback (most recent call last):
  File "/usr/local/lib/python3.7/site-packages/celery/beat.py", line 515, in setup_schedule
    self._store = self._open_schedule()
  File "/usr/local/lib/python3.7/site-packages/celery/beat.py", line 505, in _open_schedule
    return self.persistence.open(self.schedule_filename, writeback=True)
  File "/usr/local/lib/python3.7/shelve.py", line 243, in open
    return DbfilenameShelf(filename, flag, protocol, writeback)
  File "/usr/local/lib/python3.7/shelve.py", line 227, in __init__
    Shelf.__init__(self, dbm.open(filename, flag), protocol, writeback)
  File "/usr/local/lib/python3.7/dbm/__init__.py", line 94, in open
    return mod.open(file, flag, mode)
_gdbm.error: [Errno 11] Resource temporarily unavailable
[2021-04-27 06:21:58,625: ERROR/MainProcess] consumer: Cannot connect to amqp://guest:**@127.0.0.1:5672//: [Errno 111] Connection refused.
Trying again in 6.00 seconds... (3/100)

[2021-04-27 06:22:04,617: ERROR/MainProcess] consumer: Cannot connect to amqp://guest:**@127.0.0.1:5672//: [Errno 111] Connection refused.
Trying again in 8.00 seconds... (4/100)

[2021-04-27 06:22:12,649: ERROR/MainProcess] consumer: Cannot connect to amqp://guest:**@127.0.0.1:5672//: [Errno 111] Connection refused.
Trying again in 10.00 seconds... (5/100)

[2021-04-27 06:22:22,689: ERROR/MainProcess] consumer: Cannot connect to amqp://guest:**@127.0.0.1:5672//: [Errno 111] Connection refused.
Trying again in 12.00 seconds... (6/100)

[2021-04-27 06:22:34,686: ERROR/MainProcess] consumer: Cannot connect to amqp://guest:**@127.0.0.1:5672//: [Errno 111] Connection refused.
Trying again in 14.00 seconds... (7/100)

[2021-04-27 06:22:48,733: ERROR/MainProcess] consumer: Cannot connect to amqp://guest:**@127.0.0.1:5672//: [Errno 111] Connection refused.
Trying again in 16.00 seconds... (8/100)

[2021-04-27 06:23:04,760: ERROR/MainProcess] consumer: Cannot connect to amqp://guest:**@127.0.0.1:5672//: [Errno 111] Connection refused.
Trying again in 18.00 seconds... (9/100)

[2021-04-27 06:23:22,818: ERROR/MainProcess] consumer: Cannot connect to amqp://guest:**@127.0.0.1:5672//: [Errno 111] Connection refused.
Trying again in 20.00 seconds... (10/100)

[2021-04-27 06:23:42,844: ERROR/MainProcess] consumer: Cannot connect to amqp://guest:**@127.0.0.1:5672//: [Errno 111] Connection refused.
Trying again in 22.00 seconds... (11/100)

[2021-04-27 06:24:04,878: ERROR/MainProcess] consumer: Cannot connect to amqp://guest:**@127.0.0.1:5672//: [Errno 111] Connection refused.
Trying again in 24.00 seconds... (12/100)

[2021-04-27 06:24:28,917: ERROR/MainProcess] consumer: Cannot connect to amqp://guest:**@127.0.0.1:5672//: [Errno 111] Connection refused.
Trying again in 26.00 seconds... (13/100)

[2021-04-27 06:24:40,579: INFO/MainProcess] beat: Shutting down...
[2021-04-27 06:24:50,389: ERROR/MainProcess] consumer: Cannot connect to amqp://guest:**@127.0.0.1:5672//: [Errno 111] Connection refused.
Trying again in 2.00 seconds... (1/100)

[2021-04-27 06:24:52,343: INFO/Beat] beat: Starting...
[2021-04-27 06:24:52,364: ERROR/Beat] Removing corrupted schedule file 'celerybeat-schedule': error(11, 'Resource temporarily unavailable')
Traceback (most recent call last):
  File "/usr/local/lib/python3.7/site-packages/kombu/utils/objects.py", line 41, in __get__
    return obj.__dict__[self.__name__]
KeyError: 'scheduler'

During handling of the above exception, another exception occurred:

Traceback (most recent call last):
  File "/usr/local/lib/python3.7/site-packages/celery/beat.py", line 515, in setup_schedule
    self._store = self._open_schedule()
  File "/usr/local/lib/python3.7/site-packages/celery/beat.py", line 505, in _open_schedule
    return self.persistence.open(self.schedule_filename, writeback=True)
  File "/usr/local/lib/python3.7/shelve.py", line 243, in open
    return DbfilenameShelf(filename, flag, protocol, writeback)
  File "/usr/local/lib/python3.7/shelve.py", line 227, in __init__
    Shelf.__init__(self, dbm.open(filename, flag), protocol, writeback)
  File "/usr/local/lib/python3.7/dbm/__init__.py", line 94, in open
    return mod.open(file, flag, mode)
_gdbm.error: [Errno 11] Resource temporarily unavailable
[2021-04-27 06:24:52,400: ERROR/MainProcess] consumer: Cannot connect to amqp://guest:**@127.0.0.1:5672//: [Errno 111] Connection refused.
Trying again in 4.00 seconds... (2/100)

[2021-04-27 06:24:56,423: ERROR/MainProcess] consumer: Cannot connect to amqp://guest:**@127.0.0.1:5672//: [Errno 111] Connection refused.
Trying again in 6.00 seconds... (3/100)

[2021-04-27 06:25:02,413: ERROR/MainProcess] consumer: Cannot connect to amqp://guest:**@127.0.0.1:5672//: [Errno 111] Connection refused.
Trying again in 8.00 seconds... (4/100)

[2021-04-27 06:25:10,434: ERROR/MainProcess] consumer: Cannot connect to amqp://guest:**@127.0.0.1:5672//: [Errno 111] Connection refused.
Trying again in 10.00 seconds... (5/100)

[2021-04-27 06:25:20,476: ERROR/MainProcess] consumer: Cannot connect to amqp://guest:**@127.0.0.1:5672//: [Errno 111] Connection refused.
Trying again in 12.00 seconds... (6/100)

[2021-04-27 06:25:32,480: ERROR/MainProcess] consumer: Cannot connect to amqp://guest:**@127.0.0.1:5672//: [Errno 111] Connection refused.
Trying again in 14.00 seconds... (7/100)

[2021-04-27 06:25:46,525: ERROR/MainProcess] consumer: Cannot connect to amqp://guest:**@127.0.0.1:5672//: [Errno 111] Connection refused.
Trying again in 16.00 seconds... (8/100)

[2021-04-27 06:26:02,545: ERROR/MainProcess] consumer: Cannot connect to amqp://guest:**@127.0.0.1:5672//: [Errno 111] Connection refused.
Trying again in 18.00 seconds... (9/100)

[2021-04-27 06:26:20,609: ERROR/MainProcess] consumer: Cannot connect to amqp://guest:**@127.0.0.1:5672//: [Errno 111] Connection refused.
Trying again in 20.00 seconds... (10/100)

[2021-04-27 06:26:40,639: ERROR/MainProcess] consumer: Cannot connect to amqp://guest:**@127.0.0.1:5672//: [Errno 111] Connection refused.
Trying again in 22.00 seconds... (11/100)

[2021-04-27 06:26:44,414: INFO/MainProcess] beat: Shutting down...
[2021-04-27 21:42:57,324: ERROR/MainProcess] consumer: Cannot connect to amqp://guest:**@127.0.0.1:5672//: [Errno 111] Connection refused.
Trying again in 2.00 seconds... (1/100)

[2021-04-27 21:42:59,335: ERROR/MainProcess] consumer: Cannot connect to amqp://guest:**@127.0.0.1:5672//: [Errno 111] Connection refused.
Trying again in 4.00 seconds... (2/100)

[2021-04-27 21:42:59,417: INFO/Beat] beat: Starting...
[2021-04-27 21:42:59,438: ERROR/Beat] Removing corrupted schedule file 'celerybeat-schedule': error(11, 'Resource temporarily unavailable')
Traceback (most recent call last):
  File "/usr/local/lib/python3.7/site-packages/kombu/utils/objects.py", line 41, in __get__
    return obj.__dict__[self.__name__]
KeyError: 'scheduler'

During handling of the above exception, another exception occurred:

Traceback (most recent call last):
  File "/usr/local/lib/python3.7/site-packages/celery/beat.py", line 515, in setup_schedule
    self._store = self._open_schedule()
  File "/usr/local/lib/python3.7/site-packages/celery/beat.py", line 505, in _open_schedule
    return self.persistence.open(self.schedule_filename, writeback=True)
  File "/usr/local/lib/python3.7/shelve.py", line 243, in open
    return DbfilenameShelf(filename, flag, protocol, writeback)
  File "/usr/local/lib/python3.7/shelve.py", line 227, in __init__
    Shelf.__init__(self, dbm.open(filename, flag), protocol, writeback)
  File "/usr/local/lib/python3.7/dbm/__init__.py", line 94, in open
    return mod.open(file, flag, mode)
_gdbm.error: [Errno 11] Resource temporarily unavailable
[2021-04-27 21:43:03,355: ERROR/MainProcess] consumer: Cannot connect to amqp://guest:**@127.0.0.1:5672//: [Errno 111] Connection refused.
Trying again in 6.00 seconds... (3/100)

[2021-04-27 21:43:09,380: ERROR/MainProcess] consumer: Cannot connect to amqp://guest:**@127.0.0.1:5672//: [Errno 111] Connection refused.
Trying again in 8.00 seconds... (4/100)

[2021-04-27 21:43:18,545: ERROR/MainProcess] consumer: Cannot connect to amqp://guest:**@127.0.0.1:5672//: [Errno 111] Connection refused.
Trying again in 10.00 seconds... (5/100)

[2021-04-27 21:43:28,596: ERROR/MainProcess] consumer: Cannot connect to amqp://guest:**@127.0.0.1:5672//: [Errno 111] Connection refused.
Trying again in 12.00 seconds... (6/100)

[2021-04-27 21:43:40,641: ERROR/MainProcess] consumer: Cannot connect to amqp://guest:**@127.0.0.1:5672//: [Errno 111] Connection refused.
Trying again in 14.00 seconds... (7/100)

[2021-04-27 21:43:54,650: ERROR/MainProcess] consumer: Cannot connect to amqp://guest:**@127.0.0.1:5672//: [Errno 111] Connection refused.
Trying again in 16.00 seconds... (8/100)

[2021-04-27 21:44:10,704: ERROR/MainProcess] consumer: Cannot connect to amqp://guest:**@127.0.0.1:5672//: [Errno 111] Connection refused.
Trying again in 18.00 seconds... (9/100)

[2021-04-27 21:44:28,738: ERROR/MainProcess] consumer: Cannot connect to amqp://guest:**@127.0.0.1:5672//: [Errno 111] Connection refused.
Trying again in 20.00 seconds... (10/100)

[2021-04-27 21:44:48,777: ERROR/MainProcess] consumer: Cannot connect to amqp://guest:**@127.0.0.1:5672//: [Errno 111] Connection refused.
Trying again in 22.00 seconds... (11/100)

[2021-04-27 21:45:10,882: ERROR/MainProcess] consumer: Cannot connect to amqp://guest:**@127.0.0.1:5672//: [Errno 111] Connection refused.
Trying again in 24.00 seconds... (12/100)

[2021-04-27 21:45:34,936: ERROR/MainProcess] consumer: Cannot connect to amqp://guest:**@127.0.0.1:5672//: [Errno 111] Connection refused.
Trying again in 26.00 seconds... (13/100)

[2021-04-27 21:46:00,983: ERROR/MainProcess] consumer: Cannot connect to amqp://guest:**@127.0.0.1:5672//: [Errno 111] Connection refused.
Trying again in 28.00 seconds... (14/100)

[2021-04-27 21:46:29,044: ERROR/MainProcess] consumer: Cannot connect to amqp://guest:**@127.0.0.1:5672//: [Errno 111] Connection refused.
Trying again in 30.00 seconds... (15/100)

[2021-04-27 21:49:13,947: ERROR/MainProcess] consumer: Cannot connect to amqp://guest:**@127.0.0.1:5672//: [Errno 111] Connection refused.
Trying again in 2.00 seconds... (1/100)

[2021-04-27 21:49:15,922: ERROR/MainProcess] consumer: Cannot connect to amqp://guest:**@127.0.0.1:5672//: [Errno 111] Connection refused.
Trying again in 4.00 seconds... (2/100)

[2021-04-27 21:49:16,001: INFO/Beat] beat: Starting...
[2021-04-27 21:49:16,021: ERROR/Beat] Removing corrupted schedule file 'celerybeat-schedule': error(11, 'Resource temporarily unavailable')
Traceback (most recent call last):
  File "/usr/local/lib/python3.7/site-packages/kombu/utils/objects.py", line 41, in __get__
    return obj.__dict__[self.__name__]
KeyError: 'scheduler'

During handling of the above exception, another exception occurred:

Traceback (most recent call last):
  File "/usr/local/lib/python3.7/site-packages/celery/beat.py", line 515, in setup_schedule
    self._store = self._open_schedule()
  File "/usr/local/lib/python3.7/site-packages/celery/beat.py", line 505, in _open_schedule
    return self.persistence.open(self.schedule_filename, writeback=True)
  File "/usr/local/lib/python3.7/shelve.py", line 243, in open
    return DbfilenameShelf(filename, flag, protocol, writeback)
  File "/usr/local/lib/python3.7/shelve.py", line 227, in __init__
    Shelf.__init__(self, dbm.open(filename, flag), protocol, writeback)
  File "/usr/local/lib/python3.7/dbm/__init__.py", line 94, in open
    return mod.open(file, flag, mode)
_gdbm.error: [Errno 11] Resource temporarily unavailable
[2021-04-27 21:49:19,935: ERROR/MainProcess] consumer: Cannot connect to amqp://guest:**@127.0.0.1:5672//: [Errno 111] Connection refused.
Trying again in 6.00 seconds... (3/100)

[2021-04-27 21:49:25,967: ERROR/MainProcess] consumer: Cannot connect to amqp://guest:**@127.0.0.1:5672//: [Errno 111] Connection refused.
Trying again in 8.00 seconds... (4/100)

[2021-04-27 21:49:34,005: ERROR/MainProcess] consumer: Cannot connect to amqp://guest:**@127.0.0.1:5672//: [Errno 111] Connection refused.
Trying again in 10.00 seconds... (5/100)

[2021-04-27 21:49:44,044: ERROR/MainProcess] consumer: Cannot connect to amqp://guest:**@127.0.0.1:5672//: [Errno 111] Connection refused.
Trying again in 12.00 seconds... (6/100)

[2021-04-27 21:49:56,059: ERROR/MainProcess] consumer: Cannot connect to amqp://guest:**@127.0.0.1:5672//: [Errno 111] Connection refused.
Trying again in 14.00 seconds... (7/100)

[2021-04-27 21:50:10,108: ERROR/MainProcess] consumer: Cannot connect to amqp://guest:**@127.0.0.1:5672//: [Errno 111] Connection refused.
Trying again in 16.00 seconds... (8/100)

[2021-04-27 21:50:26,132: ERROR/MainProcess] consumer: Cannot connect to amqp://guest:**@127.0.0.1:5672//: [Errno 111] Connection refused.
Trying again in 18.00 seconds... (9/100)

[2021-04-27 21:50:44,199: ERROR/MainProcess] consumer: Cannot connect to amqp://guest:**@127.0.0.1:5672//: [Errno 111] Connection refused.
Trying again in 20.00 seconds... (10/100)

[2021-04-27 21:51:04,232: ERROR/MainProcess] consumer: Cannot connect to amqp://guest:**@127.0.0.1:5672//: [Errno 111] Connection refused.
Trying again in 22.00 seconds... (11/100)

[2021-04-27 21:51:26,268: ERROR/MainProcess] consumer: Cannot connect to amqp://guest:**@127.0.0.1:5672//: [Errno 111] Connection refused.
Trying again in 24.00 seconds... (12/100)

[2021-04-27 21:51:50,306: ERROR/MainProcess] consumer: Cannot connect to amqp://guest:**@127.0.0.1:5672//: [Errno 111] Connection refused.
Trying again in 26.00 seconds... (13/100)

[2021-04-27 21:52:16,351: ERROR/MainProcess] consumer: Cannot connect to amqp://guest:**@127.0.0.1:5672//: [Errno 111] Connection refused.
Trying again in 28.00 seconds... (14/100)

[2021-04-27 21:52:44,442: ERROR/MainProcess] consumer: Cannot connect to amqp://guest:**@127.0.0.1:5672//: [Errno 111] Connection refused.
Trying again in 30.00 seconds... (15/100)

[2021-04-27 21:53:14,492: ERROR/MainProcess] consumer: Cannot connect to amqp://guest:**@127.0.0.1:5672//: [Errno 111] Connection refused.
Trying again in 32.00 seconds... (16/100)

[2021-04-27 21:53:46,517: ERROR/MainProcess] consumer: Cannot connect to amqp://guest:**@127.0.0.1:5672//: [Errno 111] Connection refused.
Trying again in 32.00 seconds... (16/100)

[2021-04-27 21:54:18,584: ERROR/MainProcess] consumer: Cannot connect to amqp://guest:**@127.0.0.1:5672//: [Errno 111] Connection refused.
Trying again in 32.00 seconds... (16/100)

[2021-04-27 21:54:50,633: ERROR/MainProcess] consumer: Cannot connect to amqp://guest:**@127.0.0.1:5672//: [Errno 111] Connection refused.
Trying again in 32.00 seconds... (16/100)

[2021-04-27 21:55:22,726: ERROR/MainProcess] consumer: Cannot connect to amqp://guest:**@127.0.0.1:5672//: [Errno 111] Connection refused.
Trying again in 32.00 seconds... (16/100)

[2021-04-27 21:55:54,809: ERROR/MainProcess] consumer: Cannot connect to amqp://guest:**@127.0.0.1:5672//: [Errno 111] Connection refused.
Trying again in 32.00 seconds... (16/100)

[2021-04-27 21:56:26,867: ERROR/MainProcess] consumer: Cannot connect to amqp://guest:**@127.0.0.1:5672//: [Errno 111] Connection refused.
Trying again in 32.00 seconds... (16/100)

[2021-04-27 21:56:58,936: ERROR/MainProcess] consumer: Cannot connect to amqp://guest:**@127.0.0.1:5672//: [Errno 111] Connection refused.
Trying again in 32.00 seconds... (16/100)

[2021-04-27 21:57:31,006: ERROR/MainProcess] consumer: Cannot connect to amqp://guest:**@127.0.0.1:5672//: [Errno 111] Connection refused.
Trying again in 32.00 seconds... (16/100)

[2021-04-27 21:58:03,062: ERROR/MainProcess] consumer: Cannot connect to amqp://guest:**@127.0.0.1:5672//: [Errno 111] Connection refused.
Trying again in 32.00 seconds... (16/100)

[2021-04-27 21:58:35,132: ERROR/MainProcess] consumer: Cannot connect to amqp://guest:**@127.0.0.1:5672//: [Errno 111] Connection refused.
Trying again in 32.00 seconds... (16/100)

[2021-04-27 21:59:07,191: ERROR/MainProcess] consumer: Cannot connect to amqp://guest:**@127.0.0.1:5672//: [Errno 111] Connection refused.
Trying again in 32.00 seconds... (16/100)

[2021-04-27 21:59:39,250: ERROR/MainProcess] consumer: Cannot connect to amqp://guest:**@127.0.0.1:5672//: [Errno 111] Connection refused.
Trying again in 32.00 seconds... (16/100)

[2021-04-27 22:00:11,322: ERROR/MainProcess] consumer: Cannot connect to amqp://guest:**@127.0.0.1:5672//: [Errno 111] Connection refused.
Trying again in 32.00 seconds... (16/100)

[2021-04-27 22:00:43,388: ERROR/MainProcess] consumer: Cannot connect to amqp://guest:**@127.0.0.1:5672//: [Errno 111] Connection refused.
Trying again in 32.00 seconds... (16/100)

[2021-04-27 22:01:15,400: ERROR/MainProcess] consumer: Cannot connect to amqp://guest:**@127.0.0.1:5672//: [Errno 111] Connection refused.
Trying again in 32.00 seconds... (16/100)

[2021-04-27 22:01:47,472: ERROR/MainProcess] consumer: Cannot connect to amqp://guest:**@127.0.0.1:5672//: [Errno 111] Connection refused.
Trying again in 32.00 seconds... (16/100)

[2021-04-27 22:02:19,553: ERROR/MainProcess] consumer: Cannot connect to amqp://guest:**@127.0.0.1:5672//: [Errno 111] Connection refused.
Trying again in 32.00 seconds... (16/100)

[2021-04-27 22:02:51,642: ERROR/MainProcess] consumer: Cannot connect to amqp://guest:**@127.0.0.1:5672//: [Errno 111] Connection refused.
Trying again in 32.00 seconds... (16/100)

[2021-04-27 22:03:23,706: ERROR/MainProcess] consumer: Cannot connect to amqp://guest:**@127.0.0.1:5672//: [Errno 111] Connection refused.
Trying again in 32.00 seconds... (16/100)

[2021-04-27 22:03:55,786: ERROR/MainProcess] consumer: Cannot connect to amqp://guest:**@127.0.0.1:5672//: [Errno 111] Connection refused.
Trying again in 32.00 seconds... (16/100)

[2021-04-27 22:04:27,844: ERROR/MainProcess] consumer: Cannot connect to amqp://guest:**@127.0.0.1:5672//: [Errno 111] Connection refused.
Trying again in 32.00 seconds... (16/100)

[2021-04-27 22:04:59,924: ERROR/MainProcess] consumer: Cannot connect to amqp://guest:**@127.0.0.1:5672//: [Errno 111] Connection refused.
Trying again in 32.00 seconds... (16/100)

[2021-04-27 22:05:32,004: ERROR/MainProcess] consumer: Cannot connect to amqp://guest:**@127.0.0.1:5672//: [Errno 111] Connection refused.
Trying again in 32.00 seconds... (16/100)

[2021-04-27 22:06:04,066: ERROR/MainProcess] consumer: Cannot connect to amqp://guest:**@127.0.0.1:5672//: [Errno 111] Connection refused.
Trying again in 32.00 seconds... (16/100)

[2021-04-27 22:06:36,136: ERROR/MainProcess] consumer: Cannot connect to amqp://guest:**@127.0.0.1:5672//: [Errno 111] Connection refused.
Trying again in 32.00 seconds... (16/100)

[2021-04-27 22:07:08,196: ERROR/MainProcess] consumer: Cannot connect to amqp://guest:**@127.0.0.1:5672//: [Errno 111] Connection refused.
Trying again in 32.00 seconds... (16/100)

[2021-04-27 22:07:40,263: ERROR/MainProcess] consumer: Cannot connect to amqp://guest:**@127.0.0.1:5672//: [Errno 111] Connection refused.
Trying again in 32.00 seconds... (16/100)

[2021-04-27 22:08:12,342: ERROR/MainProcess] consumer: Cannot connect to amqp://guest:**@127.0.0.1:5672//: [Errno 111] Connection refused.
Trying again in 32.00 seconds... (16/100)

[2021-04-27 22:08:44,387: ERROR/MainProcess] consumer: Cannot connect to amqp://guest:**@127.0.0.1:5672//: [Errno 111] Connection refused.
Trying again in 32.00 seconds... (16/100)

[2021-04-27 22:09:16,447: ERROR/MainProcess] consumer: Cannot connect to amqp://guest:**@127.0.0.1:5672//: [Errno 111] Connection refused.
Trying again in 32.00 seconds... (16/100)

[2021-04-27 22:09:48,507: ERROR/MainProcess] consumer: Cannot connect to amqp://guest:**@127.0.0.1:5672//: [Errno 111] Connection refused.
Trying again in 32.00 seconds... (16/100)

[2021-04-27 22:10:20,548: ERROR/MainProcess] consumer: Cannot connect to amqp://guest:**@127.0.0.1:5672//: [Errno 111] Connection refused.
Trying again in 32.00 seconds... (16/100)

[2021-04-27 22:10:52,597: ERROR/MainProcess] consumer: Cannot connect to amqp://guest:**@127.0.0.1:5672//: [Errno 111] Connection refused.
Trying again in 32.00 seconds... (16/100)

[2021-04-27 22:11:19,809: INFO/MainProcess] beat: Shutting down...
[2021-04-27 22:11:36,297: ERROR/MainProcess] consumer: Cannot connect to amqp://guest:**@127.0.0.1:5672//: [Errno 111] Connection refused.
Trying again in 2.00 seconds... (1/100)

[2021-04-27 22:11:38,307: ERROR/MainProcess] consumer: Cannot connect to amqp://guest:**@127.0.0.1:5672//: [Errno 111] Connection refused.
Trying again in 4.00 seconds... (2/100)

[2021-04-27 22:11:38,457: INFO/Beat] beat: Starting...
[2021-04-27 22:11:38,478: ERROR/Beat] Removing corrupted schedule file 'celerybeat-schedule': error(11, 'Resource temporarily unavailable')
Traceback (most recent call last):
  File "/usr/local/lib/python3.7/site-packages/kombu/utils/objects.py", line 41, in __get__
    return obj.__dict__[self.__name__]
KeyError: 'scheduler'

During handling of the above exception, another exception occurred:

Traceback (most recent call last):
  File "/usr/local/lib/python3.7/site-packages/celery/beat.py", line 515, in setup_schedule
    self._store = self._open_schedule()
  File "/usr/local/lib/python3.7/site-packages/celery/beat.py", line 505, in _open_schedule
    return self.persistence.open(self.schedule_filename, writeback=True)
  File "/usr/local/lib/python3.7/shelve.py", line 243, in open
    return DbfilenameShelf(filename, flag, protocol, writeback)
  File "/usr/local/lib/python3.7/shelve.py", line 227, in __init__
    Shelf.__init__(self, dbm.open(filename, flag), protocol, writeback)
  File "/usr/local/lib/python3.7/dbm/__init__.py", line 94, in open
    return mod.open(file, flag, mode)
_gdbm.error: [Errno 11] Resource temporarily unavailable
[2021-04-27 22:11:42,327: ERROR/MainProcess] consumer: Cannot connect to amqp://guest:**@127.0.0.1:5672//: [Errno 111] Connection refused.
Trying again in 6.00 seconds... (3/100)

[2021-04-27 22:11:48,313: ERROR/MainProcess] consumer: Cannot connect to amqp://guest:**@127.0.0.1:5672//: [Errno 111] Connection refused.
Trying again in 8.00 seconds... (4/100)

[2021-04-27 22:11:56,341: ERROR/MainProcess] consumer: Cannot connect to amqp://guest:**@127.0.0.1:5672//: [Errno 111] Connection refused.
Trying again in 10.00 seconds... (5/100)

[2021-04-27 22:12:06,380: ERROR/MainProcess] consumer: Cannot connect to amqp://guest:**@127.0.0.1:5672//: [Errno 111] Connection refused.
Trying again in 12.00 seconds... (6/100)

[2021-04-27 22:12:18,390: ERROR/MainProcess] consumer: Cannot connect to amqp://guest:**@127.0.0.1:5672//: [Errno 111] Connection refused.
Trying again in 14.00 seconds... (7/100)

[2021-04-27 22:12:32,443: ERROR/MainProcess] consumer: Cannot connect to amqp://guest:**@127.0.0.1:5672//: [Errno 111] Connection refused.
Trying again in 16.00 seconds... (8/100)

[2021-04-27 22:12:48,458: ERROR/MainProcess] consumer: Cannot connect to amqp://guest:**@127.0.0.1:5672//: [Errno 111] Connection refused.
Trying again in 18.00 seconds... (9/100)

[2021-04-27 22:13:06,522: ERROR/MainProcess] consumer: Cannot connect to amqp://guest:**@127.0.0.1:5672//: [Errno 111] Connection refused.
Trying again in 20.00 seconds... (10/100)

[2021-04-27 22:13:26,563: ERROR/MainProcess] consumer: Cannot connect to amqp://guest:**@127.0.0.1:5672//: [Errno 111] Connection refused.
Trying again in 22.00 seconds... (11/100)

[2021-04-27 22:13:48,610: ERROR/MainProcess] consumer: Cannot connect to amqp://guest:**@127.0.0.1:5672//: [Errno 111] Connection refused.
Trying again in 24.00 seconds... (12/100)

[2021-04-27 22:14:12,699: ERROR/MainProcess] consumer: Cannot connect to amqp://guest:**@127.0.0.1:5672//: [Errno 111] Connection refused.
Trying again in 26.00 seconds... (13/100)

[2021-04-27 22:14:38,741: ERROR/MainProcess] consumer: Cannot connect to amqp://guest:**@127.0.0.1:5672//: [Errno 111] Connection refused.
Trying again in 28.00 seconds... (14/100)

[2021-04-27 22:15:06,796: ERROR/MainProcess] consumer: Cannot connect to amqp://guest:**@127.0.0.1:5672//: [Errno 111] Connection refused.
Trying again in 30.00 seconds... (15/100)

[2021-04-27 22:15:36,858: ERROR/MainProcess] consumer: Cannot connect to amqp://guest:**@127.0.0.1:5672//: [Errno 111] Connection refused.
Trying again in 32.00 seconds... (16/100)

[2021-04-27 22:16:08,921: ERROR/MainProcess] consumer: Cannot connect to amqp://guest:**@127.0.0.1:5672//: [Errno 111] Connection refused.
Trying again in 32.00 seconds... (16/100)

[2021-04-27 22:16:40,982: ERROR/MainProcess] consumer: Cannot connect to amqp://guest:**@127.0.0.1:5672//: [Errno 111] Connection refused.
Trying again in 32.00 seconds... (16/100)

[2021-04-27 22:17:13,051: ERROR/MainProcess] consumer: Cannot connect to amqp://guest:**@127.0.0.1:5672//: [Errno 111] Connection refused.
Trying again in 32.00 seconds... (16/100)

[2021-04-27 22:17:45,079: ERROR/MainProcess] consumer: Cannot connect to amqp://guest:**@127.0.0.1:5672//: [Errno 111] Connection refused.
Trying again in 32.00 seconds... (16/100)

[2021-04-27 22:18:17,161: ERROR/MainProcess] consumer: Cannot connect to amqp://guest:**@127.0.0.1:5672//: [Errno 111] Connection refused.
Trying again in 32.00 seconds... (16/100)

[2021-04-27 22:18:49,211: ERROR/MainProcess] consumer: Cannot connect to amqp://guest:**@127.0.0.1:5672//: [Errno 111] Connection refused.
Trying again in 32.00 seconds... (16/100)

[2021-04-27 22:19:21,250: ERROR/MainProcess] consumer: Cannot connect to amqp://guest:**@127.0.0.1:5672//: [Errno 111] Connection refused.
Trying again in 32.00 seconds... (16/100)

[2021-04-27 22:19:53,319: ERROR/MainProcess] consumer: Cannot connect to amqp://guest:**@127.0.0.1:5672//: [Errno 111] Connection refused.
Trying again in 32.00 seconds... (16/100)

[2021-04-27 22:20:08,241: INFO/MainProcess] beat: Shutting down...
[2021-04-27 23:33:30,159: ERROR/MainProcess] consumer: Cannot connect to amqp://guest:**@127.0.0.1:5672//: [Errno 111] Connection refused.
Trying again in 2.00 seconds... (1/100)

[2021-04-27 23:33:32,071: INFO/Beat] beat: Starting...
[2021-04-27 23:33:32,096: ERROR/Beat] Removing corrupted schedule file 'celerybeat-schedule': error(11, 'Resource temporarily unavailable')
Traceback (most recent call last):
  File "/usr/local/lib/python3.7/site-packages/kombu/utils/objects.py", line 41, in __get__
    return obj.__dict__[self.__name__]
KeyError: 'scheduler'

During handling of the above exception, another exception occurred:

Traceback (most recent call last):
  File "/usr/local/lib/python3.7/site-packages/celery/beat.py", line 515, in setup_schedule
    self._store = self._open_schedule()
  File "/usr/local/lib/python3.7/site-packages/celery/beat.py", line 505, in _open_schedule
    return self.persistence.open(self.schedule_filename, writeback=True)
  File "/usr/local/lib/python3.7/shelve.py", line 243, in open
    return DbfilenameShelf(filename, flag, protocol, writeback)
  File "/usr/local/lib/python3.7/shelve.py", line 227, in __init__
    Shelf.__init__(self, dbm.open(filename, flag), protocol, writeback)
  File "/usr/local/lib/python3.7/dbm/__init__.py", line 94, in open
    return mod.open(file, flag, mode)
_gdbm.error: [Errno 11] Resource temporarily unavailable
[2021-04-27 23:33:32,174: ERROR/MainProcess] consumer: Cannot connect to amqp://guest:**@127.0.0.1:5672//: [Errno 111] Connection refused.
Trying again in 4.00 seconds... (2/100)

[2021-04-27 23:33:36,200: ERROR/MainProcess] consumer: Cannot connect to amqp://guest:**@127.0.0.1:5672//: [Errno 111] Connection refused.
Trying again in 6.00 seconds... (3/100)

[2021-04-27 23:33:42,188: ERROR/MainProcess] consumer: Cannot connect to amqp://guest:**@127.0.0.1:5672//: [Errno 111] Connection refused.
Trying again in 8.00 seconds... (4/100)

[2021-04-27 23:33:50,215: ERROR/MainProcess] consumer: Cannot connect to amqp://guest:**@127.0.0.1:5672//: [Errno 111] Connection refused.
Trying again in 10.00 seconds... (5/100)

[2021-04-27 23:34:00,250: ERROR/MainProcess] consumer: Cannot connect to amqp://guest:**@127.0.0.1:5672//: [Errno 111] Connection refused.
Trying again in 12.00 seconds... (6/100)

[2021-04-27 23:34:12,253: ERROR/MainProcess] consumer: Cannot connect to amqp://guest:**@127.0.0.1:5672//: [Errno 111] Connection refused.
Trying again in 14.00 seconds... (7/100)

[2021-04-27 23:34:26,310: ERROR/MainProcess] consumer: Cannot connect to amqp://guest:**@127.0.0.1:5672//: [Errno 111] Connection refused.
Trying again in 16.00 seconds... (8/100)

[2021-04-27 23:34:42,318: ERROR/MainProcess] consumer: Cannot connect to amqp://guest:**@127.0.0.1:5672//: [Errno 111] Connection refused.
Trying again in 18.00 seconds... (9/100)

[2021-04-27 23:35:00,384: ERROR/MainProcess] consumer: Cannot connect to amqp://guest:**@127.0.0.1:5672//: [Errno 111] Connection refused.
Trying again in 20.00 seconds... (10/100)

[2021-04-27 23:35:20,422: ERROR/MainProcess] consumer: Cannot connect to amqp://guest:**@127.0.0.1:5672//: [Errno 111] Connection refused.
Trying again in 22.00 seconds... (11/100)

[2021-04-27 23:35:42,463: ERROR/MainProcess] consumer: Cannot connect to amqp://guest:**@127.0.0.1:5672//: [Errno 111] Connection refused.
Trying again in 24.00 seconds... (12/100)

[2021-04-27 23:35:46,302: INFO/MainProcess] beat: Shutting down...
[2021-04-27 23:42:22,885: ERROR/MainProcess] consumer: Cannot connect to amqp://guest:**@127.0.0.1:5672//: [Errno 111] Connection refused.
Trying again in 2.00 seconds... (1/100)

[2021-04-27 23:42:24,841: INFO/Beat] beat: Starting...
[2021-04-27 23:42:24,863: ERROR/Beat] Removing corrupted schedule file 'celerybeat-schedule': error(11, 'Resource temporarily unavailable')
Traceback (most recent call last):
  File "/usr/local/lib/python3.7/site-packages/kombu/utils/objects.py", line 41, in __get__
    return obj.__dict__[self.__name__]
KeyError: 'scheduler'

During handling of the above exception, another exception occurred:

Traceback (most recent call last):
  File "/usr/local/lib/python3.7/site-packages/celery/beat.py", line 515, in setup_schedule
    self._store = self._open_schedule()
  File "/usr/local/lib/python3.7/site-packages/celery/beat.py", line 505, in _open_schedule
    return self.persistence.open(self.schedule_filename, writeback=True)
  File "/usr/local/lib/python3.7/shelve.py", line 243, in open
    return DbfilenameShelf(filename, flag, protocol, writeback)
  File "/usr/local/lib/python3.7/shelve.py", line 227, in __init__
    Shelf.__init__(self, dbm.open(filename, flag), protocol, writeback)
  File "/usr/local/lib/python3.7/dbm/__init__.py", line 94, in open
    return mod.open(file, flag, mode)
_gdbm.error: [Errno 11] Resource temporarily unavailable
[2021-04-27 23:42:24,901: ERROR/MainProcess] consumer: Cannot connect to amqp://guest:**@127.0.0.1:5672//: [Errno 111] Connection refused.
Trying again in 4.00 seconds... (2/100)

[2021-04-27 23:42:28,922: ERROR/MainProcess] consumer: Cannot connect to amqp://guest:**@127.0.0.1:5672//: [Errno 111] Connection refused.
Trying again in 6.00 seconds... (3/100)

[2021-04-27 23:42:34,951: ERROR/MainProcess] consumer: Cannot connect to amqp://guest:**@127.0.0.1:5672//: [Errno 111] Connection refused.
Trying again in 8.00 seconds... (4/100)

[2021-04-27 23:42:42,946: ERROR/MainProcess] consumer: Cannot connect to amqp://guest:**@127.0.0.1:5672//: [Errno 111] Connection refused.
Trying again in 10.00 seconds... (5/100)

[2021-04-27 23:42:52,975: ERROR/MainProcess] consumer: Cannot connect to amqp://guest:**@127.0.0.1:5672//: [Errno 111] Connection refused.
Trying again in 12.00 seconds... (6/100)

[2021-04-27 23:43:05,023: ERROR/MainProcess] consumer: Cannot connect to amqp://guest:**@127.0.0.1:5672//: [Errno 111] Connection refused.
Trying again in 14.00 seconds... (7/100)

[2021-04-27 23:43:19,036: ERROR/MainProcess] consumer: Cannot connect to amqp://guest:**@127.0.0.1:5672//: [Errno 111] Connection refused.
Trying again in 16.00 seconds... (8/100)

[2021-04-27 23:43:35,088: ERROR/MainProcess] consumer: Cannot connect to amqp://guest:**@127.0.0.1:5672//: [Errno 111] Connection refused.
Trying again in 18.00 seconds... (9/100)

[2021-04-27 23:43:53,109: ERROR/MainProcess] consumer: Cannot connect to amqp://guest:**@127.0.0.1:5672//: [Errno 111] Connection refused.
Trying again in 20.00 seconds... (10/100)

[2021-04-27 23:44:13,126: ERROR/MainProcess] consumer: Cannot connect to amqp://guest:**@127.0.0.1:5672//: [Errno 111] Connection refused.
Trying again in 22.00 seconds... (11/100)

[2021-04-27 23:44:35,197: ERROR/MainProcess] consumer: Cannot connect to amqp://guest:**@127.0.0.1:5672//: [Errno 111] Connection refused.
Trying again in 24.00 seconds... (12/100)

[2021-04-27 23:44:59,248: ERROR/MainProcess] consumer: Cannot connect to amqp://guest:**@127.0.0.1:5672//: [Errno 111] Connection refused.
Trying again in 26.00 seconds... (13/100)

[2021-04-27 23:45:25,303: ERROR/MainProcess] consumer: Cannot connect to amqp://guest:**@127.0.0.1:5672//: [Errno 111] Connection refused.
Trying again in 28.00 seconds... (14/100)

[2021-04-27 23:45:53,351: ERROR/MainProcess] consumer: Cannot connect to amqp://guest:**@127.0.0.1:5672//: [Errno 111] Connection refused.
Trying again in 30.00 seconds... (15/100)

[2021-04-27 23:46:23,399: ERROR/MainProcess] consumer: Cannot connect to amqp://guest:**@127.0.0.1:5672//: [Errno 111] Connection refused.
Trying again in 32.00 seconds... (16/100)

[2021-04-27 23:46:55,470: ERROR/MainProcess] consumer: Cannot connect to amqp://guest:**@127.0.0.1:5672//: [Errno 111] Connection refused.
Trying again in 32.00 seconds... (16/100)

[2021-04-27 23:47:27,520: ERROR/MainProcess] consumer: Cannot connect to amqp://guest:**@127.0.0.1:5672//: [Errno 111] Connection refused.
Trying again in 32.00 seconds... (16/100)

[2021-04-27 23:47:59,603: ERROR/MainProcess] consumer: Cannot connect to amqp://guest:**@127.0.0.1:5672//: [Errno 111] Connection refused.
Trying again in 32.00 seconds... (16/100)

[2021-04-27 23:48:31,675: ERROR/MainProcess] consumer: Cannot connect to amqp://guest:**@127.0.0.1:5672//: [Errno 111] Connection refused.
Trying again in 32.00 seconds... (16/100)

[2021-04-27 23:49:03,733: ERROR/MainProcess] consumer: Cannot connect to amqp://guest:**@127.0.0.1:5672//: [Errno 111] Connection refused.
Trying again in 32.00 seconds... (16/100)

[2021-04-27 23:49:35,788: ERROR/MainProcess] consumer: Cannot connect to amqp://guest:**@127.0.0.1:5672//: [Errno 111] Connection refused.
Trying again in 32.00 seconds... (16/100)

[2021-04-27 23:50:07,829: ERROR/MainProcess] consumer: Cannot connect to amqp://guest:**@127.0.0.1:5672//: [Errno 111] Connection refused.
Trying again in 32.00 seconds... (16/100)

[2021-04-27 23:50:39,883: ERROR/MainProcess] consumer: Cannot connect to amqp://guest:**@127.0.0.1:5672//: [Errno 111] Connection refused.
Trying again in 32.00 seconds... (16/100)

[2021-04-27 23:51:11,953: ERROR/MainProcess] consumer: Cannot connect to amqp://guest:**@127.0.0.1:5672//: [Errno 111] Connection refused.
Trying again in 32.00 seconds... (16/100)

[2021-04-27 23:51:44,026: ERROR/MainProcess] consumer: Cannot connect to amqp://guest:**@127.0.0.1:5672//: [Errno 111] Connection refused.
Trying again in 32.00 seconds... (16/100)

[2021-04-27 23:52:16,082: ERROR/MainProcess] consumer: Cannot connect to amqp://guest:**@127.0.0.1:5672//: [Errno 111] Connection refused.
Trying again in 32.00 seconds... (16/100)

[2021-04-27 23:52:48,135: ERROR/MainProcess] consumer: Cannot connect to amqp://guest:**@127.0.0.1:5672//: [Errno 111] Connection refused.
Trying again in 32.00 seconds... (16/100)

[2021-04-27 23:53:20,186: ERROR/MainProcess] consumer: Cannot connect to amqp://guest:**@127.0.0.1:5672//: [Errno 111] Connection refused.
Trying again in 32.00 seconds... (16/100)

[2021-04-27 23:53:52,255: ERROR/MainProcess] consumer: Cannot connect to amqp://guest:**@127.0.0.1:5672//: [Errno 111] Connection refused.
Trying again in 32.00 seconds... (16/100)

[2021-04-27 23:54:24,329: ERROR/MainProcess] consumer: Cannot connect to amqp://guest:**@127.0.0.1:5672//: [Errno 111] Connection refused.
Trying again in 32.00 seconds... (16/100)

[2021-04-27 23:54:56,403: ERROR/MainProcess] consumer: Cannot connect to amqp://guest:**@127.0.0.1:5672//: [Errno 111] Connection refused.
Trying again in 32.00 seconds... (16/100)

[2021-04-27 23:55:28,466: ERROR/MainProcess] consumer: Cannot connect to amqp://guest:**@127.0.0.1:5672//: [Errno 111] Connection refused.
Trying again in 32.00 seconds... (16/100)

[2021-04-27 23:56:00,544: ERROR/MainProcess] consumer: Cannot connect to amqp://guest:**@127.0.0.1:5672//: [Errno 111] Connection refused.
Trying again in 32.00 seconds... (16/100)

[2021-04-27 23:56:32,592: ERROR/MainProcess] consumer: Cannot connect to amqp://guest:**@127.0.0.1:5672//: [Errno 111] Connection refused.
Trying again in 32.00 seconds... (16/100)

[2021-04-27 23:57:04,640: ERROR/MainProcess] consumer: Cannot connect to amqp://guest:**@127.0.0.1:5672//: [Errno 111] Connection refused.
Trying again in 32.00 seconds... (16/100)

[2021-04-27 23:57:36,705: ERROR/MainProcess] consumer: Cannot connect to amqp://guest:**@127.0.0.1:5672//: [Errno 111] Connection refused.
Trying again in 32.00 seconds... (16/100)

[2021-04-27 23:58:08,725: ERROR/MainProcess] consumer: Cannot connect to amqp://guest:**@127.0.0.1:5672//: [Errno 111] Connection refused.
Trying again in 32.00 seconds... (16/100)

[2021-04-27 23:58:40,800: ERROR/MainProcess] consumer: Cannot connect to amqp://guest:**@127.0.0.1:5672//: [Errno 111] Connection refused.
Trying again in 32.00 seconds... (16/100)

[2021-04-27 23:59:12,867: ERROR/MainProcess] consumer: Cannot connect to amqp://guest:**@127.0.0.1:5672//: [Errno 111] Connection refused.
Trying again in 32.00 seconds... (16/100)

[2021-04-27 23:59:44,931: ERROR/MainProcess] consumer: Cannot connect to amqp://guest:**@127.0.0.1:5672//: [Errno 111] Connection refused.
Trying again in 32.00 seconds... (16/100)

[2021-04-28 00:00:17,010: ERROR/MainProcess] consumer: Cannot connect to amqp://guest:**@127.0.0.1:5672//: [Errno 111] Connection refused.
Trying again in 32.00 seconds... (16/100)

[2021-04-28 00:00:49,083: ERROR/MainProcess] consumer: Cannot connect to amqp://guest:**@127.0.0.1:5672//: [Errno 111] Connection refused.
Trying again in 32.00 seconds... (16/100)

[2021-04-28 00:01:21,141: ERROR/MainProcess] consumer: Cannot connect to amqp://guest:**@127.0.0.1:5672//: [Errno 111] Connection refused.
Trying again in 32.00 seconds... (16/100)

[2021-04-28 00:01:53,206: ERROR/MainProcess] consumer: Cannot connect to amqp://guest:**@127.0.0.1:5672//: [Errno 111] Connection refused.
Trying again in 32.00 seconds... (16/100)

[2021-04-28 00:02:25,257: ERROR/MainProcess] consumer: Cannot connect to amqp://guest:**@127.0.0.1:5672//: [Errno 111] Connection refused.
Trying again in 32.00 seconds... (16/100)

[2021-04-28 00:02:57,315: ERROR/MainProcess] consumer: Cannot connect to amqp://guest:**@127.0.0.1:5672//: [Errno 111] Connection refused.
Trying again in 32.00 seconds... (16/100)

[2021-04-28 00:03:29,384: ERROR/MainProcess] consumer: Cannot connect to amqp://guest:**@127.0.0.1:5672//: [Errno 111] Connection refused.
Trying again in 32.00 seconds... (16/100)

[2021-04-28 00:04:01,481: ERROR/MainProcess] consumer: Cannot connect to amqp://guest:**@127.0.0.1:5672//: [Errno 111] Connection refused.
Trying again in 32.00 seconds... (16/100)

[2021-04-28 00:04:33,545: ERROR/MainProcess] consumer: Cannot connect to amqp://guest:**@127.0.0.1:5672//: [Errno 111] Connection refused.
Trying again in 32.00 seconds... (16/100)

[2021-04-28 00:05:05,626: ERROR/MainProcess] consumer: Cannot connect to amqp://guest:**@127.0.0.1:5672//: [Errno 111] Connection refused.
Trying again in 32.00 seconds... (16/100)

[2021-04-28 00:05:37,664: ERROR/MainProcess] consumer: Cannot connect to amqp://guest:**@127.0.0.1:5672//: [Errno 111] Connection refused.
Trying again in 32.00 seconds... (16/100)

[2021-04-28 00:06:09,726: ERROR/MainProcess] consumer: Cannot connect to amqp://guest:**@127.0.0.1:5672//: [Errno 111] Connection refused.
Trying again in 32.00 seconds... (16/100)

[2021-04-28 00:06:41,812: ERROR/MainProcess] consumer: Cannot connect to amqp://guest:**@127.0.0.1:5672//: [Errno 111] Connection refused.
Trying again in 32.00 seconds... (16/100)

[2021-04-28 00:07:13,893: ERROR/MainProcess] consumer: Cannot connect to amqp://guest:**@127.0.0.1:5672//: [Errno 111] Connection refused.
Trying again in 32.00 seconds... (16/100)

[2021-04-28 00:07:45,948: ERROR/MainProcess] consumer: Cannot connect to amqp://guest:**@127.0.0.1:5672//: [Errno 111] Connection refused.
Trying again in 32.00 seconds... (16/100)

[2021-04-28 00:08:18,025: ERROR/MainProcess] consumer: Cannot connect to amqp://guest:**@127.0.0.1:5672//: [Errno 111] Connection refused.
Trying again in 32.00 seconds... (16/100)

[2021-04-28 00:08:50,077: ERROR/MainProcess] consumer: Cannot connect to amqp://guest:**@127.0.0.1:5672//: [Errno 111] Connection refused.
Trying again in 32.00 seconds... (16/100)

[2021-04-28 00:09:22,159: ERROR/MainProcess] consumer: Cannot connect to amqp://guest:**@127.0.0.1:5672//: [Errno 111] Connection refused.
Trying again in 32.00 seconds... (16/100)

[2021-04-28 00:09:54,224: ERROR/MainProcess] consumer: Cannot connect to amqp://guest:**@127.0.0.1:5672//: [Errno 111] Connection refused.
Trying again in 32.00 seconds... (16/100)

[2021-04-28 00:10:26,292: ERROR/MainProcess] consumer: Cannot connect to amqp://guest:**@127.0.0.1:5672//: [Errno 111] Connection refused.
Trying again in 32.00 seconds... (16/100)

[2021-04-28 00:10:58,378: ERROR/MainProcess] consumer: Cannot connect to amqp://guest:**@127.0.0.1:5672//: [Errno 111] Connection refused.
Trying again in 32.00 seconds... (16/100)

[2021-04-28 00:11:30,463: ERROR/MainProcess] consumer: Cannot connect to amqp://guest:**@127.0.0.1:5672//: [Errno 111] Connection refused.
Trying again in 32.00 seconds... (16/100)

[2021-04-28 00:12:02,553: ERROR/MainProcess] consumer: Cannot connect to amqp://guest:**@127.0.0.1:5672//: [Errno 111] Connection refused.
Trying again in 32.00 seconds... (16/100)

[2021-04-28 00:12:34,641: ERROR/MainProcess] consumer: Cannot connect to amqp://guest:**@127.0.0.1:5672//: [Errno 111] Connection refused.
Trying again in 32.00 seconds... (16/100)

[2021-04-28 00:13:06,683: ERROR/MainProcess] consumer: Cannot connect to amqp://guest:**@127.0.0.1:5672//: [Errno 111] Connection refused.
Trying again in 32.00 seconds... (16/100)

[2021-04-28 00:13:38,760: ERROR/MainProcess] consumer: Cannot connect to amqp://guest:**@127.0.0.1:5672//: [Errno 111] Connection refused.
Trying again in 32.00 seconds... (16/100)

[2021-04-28 00:14:10,831: ERROR/MainProcess] consumer: Cannot connect to amqp://guest:**@127.0.0.1:5672//: [Errno 111] Connection refused.
Trying again in 32.00 seconds... (16/100)

[2021-04-28 00:14:42,911: ERROR/MainProcess] consumer: Cannot connect to amqp://guest:**@127.0.0.1:5672//: [Errno 111] Connection refused.
Trying again in 32.00 seconds... (16/100)

[2021-04-28 00:15:15,024: ERROR/MainProcess] consumer: Cannot connect to amqp://guest:**@127.0.0.1:5672//: [Errno 111] Connection refused.
Trying again in 32.00 seconds... (16/100)

[2021-04-28 00:15:47,106: ERROR/MainProcess] consumer: Cannot connect to amqp://guest:**@127.0.0.1:5672//: [Errno 111] Connection refused.
Trying again in 32.00 seconds... (16/100)

[2021-04-28 00:16:19,159: ERROR/MainProcess] consumer: Cannot connect to amqp://guest:**@127.0.0.1:5672//: [Errno 111] Connection refused.
Trying again in 32.00 seconds... (16/100)

[2021-04-28 00:16:51,236: ERROR/MainProcess] consumer: Cannot connect to amqp://guest:**@127.0.0.1:5672//: [Errno 111] Connection refused.
Trying again in 32.00 seconds... (16/100)

[2021-04-28 00:17:23,308: ERROR/MainProcess] consumer: Cannot connect to amqp://guest:**@127.0.0.1:5672//: [Errno 111] Connection refused.
Trying again in 32.00 seconds... (16/100)

[2021-04-28 00:17:55,373: ERROR/MainProcess] consumer: Cannot connect to amqp://guest:**@127.0.0.1:5672//: [Errno 111] Connection refused.
Trying again in 32.00 seconds... (16/100)

[2021-04-28 00:18:27,437: ERROR/MainProcess] consumer: Cannot connect to amqp://guest:**@127.0.0.1:5672//: [Errno 111] Connection refused.
Trying again in 32.00 seconds... (16/100)

[2021-04-28 00:18:59,479: ERROR/MainProcess] consumer: Cannot connect to amqp://guest:**@127.0.0.1:5672//: [Errno 111] Connection refused.
Trying again in 32.00 seconds... (16/100)

[2021-04-28 00:19:31,549: ERROR/MainProcess] consumer: Cannot connect to amqp://guest:**@127.0.0.1:5672//: [Errno 111] Connection refused.
Trying again in 32.00 seconds... (16/100)

[2021-04-28 00:20:03,610: ERROR/MainProcess] consumer: Cannot connect to amqp://guest:**@127.0.0.1:5672//: [Errno 111] Connection refused.
Trying again in 32.00 seconds... (16/100)

[2021-04-28 00:20:35,639: ERROR/MainProcess] consumer: Cannot connect to amqp://guest:**@127.0.0.1:5672//: [Errno 111] Connection refused.
Trying again in 32.00 seconds... (16/100)

[2021-04-28 00:21:07,729: ERROR/MainProcess] consumer: Cannot connect to amqp://guest:**@127.0.0.1:5672//: [Errno 111] Connection refused.
Trying again in 32.00 seconds... (16/100)

[2021-04-28 00:21:17,163: INFO/MainProcess] beat: Shutting down...
[2021-04-29 07:09:58,868: ERROR/MainProcess] consumer: Cannot connect to amqp://guest:**@127.0.0.1:5672//: [Errno 111] Connection refused.
Trying again in 2.00 seconds... (1/100)

[2021-04-29 07:10:00,889: ERROR/MainProcess] consumer: Cannot connect to amqp://guest:**@127.0.0.1:5672//: [Errno 111] Connection refused.
Trying again in 4.00 seconds... (2/100)

[2021-04-29 07:10:01,058: INFO/Beat] beat: Starting...
[2021-04-29 07:10:01,089: ERROR/Beat] Removing corrupted schedule file 'celerybeat-schedule': error(11, 'Resource temporarily unavailable')
Traceback (most recent call last):
  File "/usr/local/lib/python3.7/site-packages/kombu/utils/objects.py", line 41, in __get__
    return obj.__dict__[self.__name__]
KeyError: 'scheduler'

During handling of the above exception, another exception occurred:

Traceback (most recent call last):
  File "/usr/local/lib/python3.7/site-packages/celery/beat.py", line 515, in setup_schedule
    self._store = self._open_schedule()
  File "/usr/local/lib/python3.7/site-packages/celery/beat.py", line 505, in _open_schedule
    return self.persistence.open(self.schedule_filename, writeback=True)
  File "/usr/local/lib/python3.7/shelve.py", line 243, in open
    return DbfilenameShelf(filename, flag, protocol, writeback)
  File "/usr/local/lib/python3.7/shelve.py", line 227, in __init__
    Shelf.__init__(self, dbm.open(filename, flag), protocol, writeback)
  File "/usr/local/lib/python3.7/dbm/__init__.py", line 94, in open
    return mod.open(file, flag, mode)
_gdbm.error: [Errno 11] Resource temporarily unavailable
[2021-04-29 07:10:04,916: ERROR/MainProcess] consumer: Cannot connect to amqp://guest:**@127.0.0.1:5672//: [Errno 111] Connection refused.
Trying again in 6.00 seconds... (3/100)

[2021-04-29 07:10:10,905: ERROR/MainProcess] consumer: Cannot connect to amqp://guest:**@127.0.0.1:5672//: [Errno 111] Connection refused.
Trying again in 8.00 seconds... (4/100)

[2021-04-29 07:10:18,940: ERROR/MainProcess] consumer: Cannot connect to amqp://guest:**@127.0.0.1:5672//: [Errno 111] Connection refused.
Trying again in 10.00 seconds... (5/100)

[2021-04-29 07:10:28,978: ERROR/MainProcess] consumer: Cannot connect to amqp://guest:**@127.0.0.1:5672//: [Errno 111] Connection refused.
Trying again in 12.00 seconds... (6/100)

[2021-04-29 07:10:40,980: ERROR/MainProcess] consumer: Cannot connect to amqp://guest:**@127.0.0.1:5672//: [Errno 111] Connection refused.
Trying again in 14.00 seconds... (7/100)

[2021-04-29 07:10:55,031: ERROR/MainProcess] consumer: Cannot connect to amqp://guest:**@127.0.0.1:5672//: [Errno 111] Connection refused.
Trying again in 16.00 seconds... (8/100)

[2021-04-29 07:11:11,041: ERROR/MainProcess] consumer: Cannot connect to amqp://guest:**@127.0.0.1:5672//: [Errno 111] Connection refused.
Trying again in 18.00 seconds... (9/100)

[2021-04-29 07:11:29,106: ERROR/MainProcess] consumer: Cannot connect to amqp://guest:**@127.0.0.1:5672//: [Errno 111] Connection refused.
Trying again in 20.00 seconds... (10/100)

[2021-04-29 07:11:49,122: ERROR/MainProcess] consumer: Cannot connect to amqp://guest:**@127.0.0.1:5672//: [Errno 111] Connection refused.
Trying again in 22.00 seconds... (11/100)

[2021-04-29 07:12:11,162: ERROR/MainProcess] consumer: Cannot connect to amqp://guest:**@127.0.0.1:5672//: [Errno 111] Connection refused.
Trying again in 24.00 seconds... (12/100)

[2021-04-29 07:12:35,230: ERROR/MainProcess] consumer: Cannot connect to amqp://guest:**@127.0.0.1:5672//: [Errno 111] Connection refused.
Trying again in 26.00 seconds... (13/100)

[2021-04-29 07:13:01,275: ERROR/MainProcess] consumer: Cannot connect to amqp://guest:**@127.0.0.1:5672//: [Errno 111] Connection refused.
Trying again in 28.00 seconds... (14/100)

[2021-04-29 07:13:29,320: ERROR/MainProcess] consumer: Cannot connect to amqp://guest:**@127.0.0.1:5672//: [Errno 111] Connection refused.
Trying again in 30.00 seconds... (15/100)

[2021-04-29 07:13:59,381: ERROR/MainProcess] consumer: Cannot connect to amqp://guest:**@127.0.0.1:5672//: [Errno 111] Connection refused.
Trying again in 32.00 seconds... (16/100)

[2021-04-29 07:14:31,454: ERROR/MainProcess] consumer: Cannot connect to amqp://guest:**@127.0.0.1:5672//: [Errno 111] Connection refused.
Trying again in 32.00 seconds... (16/100)

[2021-04-29 07:15:03,499: ERROR/MainProcess] consumer: Cannot connect to amqp://guest:**@127.0.0.1:5672//: [Errno 111] Connection refused.
Trying again in 32.00 seconds... (16/100)

[2021-04-29 07:15:35,547: ERROR/MainProcess] consumer: Cannot connect to amqp://guest:**@127.0.0.1:5672//: [Errno 111] Connection refused.
Trying again in 32.00 seconds... (16/100)

[2021-04-29 07:16:07,577: ERROR/MainProcess] consumer: Cannot connect to amqp://guest:**@127.0.0.1:5672//: [Errno 111] Connection refused.
Trying again in 32.00 seconds... (16/100)

[2021-04-29 07:16:39,634: ERROR/MainProcess] consumer: Cannot connect to amqp://guest:**@127.0.0.1:5672//: [Errno 111] Connection refused.
Trying again in 32.00 seconds... (16/100)

[2021-04-29 07:17:11,696: ERROR/MainProcess] consumer: Cannot connect to amqp://guest:**@127.0.0.1:5672//: [Errno 111] Connection refused.
Trying again in 32.00 seconds... (16/100)

[2021-04-29 07:17:43,761: ERROR/MainProcess] consumer: Cannot connect to amqp://guest:**@127.0.0.1:5672//: [Errno 111] Connection refused.
Trying again in 32.00 seconds... (16/100)

[2021-04-29 07:18:15,833: ERROR/MainProcess] consumer: Cannot connect to amqp://guest:**@127.0.0.1:5672//: [Errno 111] Connection refused.
Trying again in 32.00 seconds... (16/100)

[2021-04-29 07:18:47,900: ERROR/MainProcess] consumer: Cannot connect to amqp://guest:**@127.0.0.1:5672//: [Errno 111] Connection refused.
Trying again in 32.00 seconds... (16/100)

[2021-04-29 07:19:19,963: ERROR/MainProcess] consumer: Cannot connect to amqp://guest:**@127.0.0.1:5672//: [Errno 111] Connection refused.
Trying again in 32.00 seconds... (16/100)

[2021-04-29 07:19:52,027: ERROR/MainProcess] consumer: Cannot connect to amqp://guest:**@127.0.0.1:5672//: [Errno 111] Connection refused.
Trying again in 32.00 seconds... (16/100)

[2021-04-29 07:20:24,095: ERROR/MainProcess] consumer: Cannot connect to amqp://guest:**@127.0.0.1:5672//: [Errno 111] Connection refused.
Trying again in 32.00 seconds... (16/100)

[2021-04-29 07:20:56,153: ERROR/MainProcess] consumer: Cannot connect to amqp://guest:**@127.0.0.1:5672//: [Errno 111] Connection refused.
Trying again in 32.00 seconds... (16/100)

[2021-04-29 07:21:28,216: ERROR/MainProcess] consumer: Cannot connect to amqp://guest:**@127.0.0.1:5672//: [Errno 111] Connection refused.
Trying again in 32.00 seconds... (16/100)

[2021-04-29 07:22:00,311: ERROR/MainProcess] consumer: Cannot connect to amqp://guest:**@127.0.0.1:5672//: [Errno 111] Connection refused.
Trying again in 32.00 seconds... (16/100)

[2021-04-29 07:22:32,371: ERROR/MainProcess] consumer: Cannot connect to amqp://guest:**@127.0.0.1:5672//: [Errno 111] Connection refused.
Trying again in 32.00 seconds... (16/100)

[2021-04-29 07:22:39,677: INFO/MainProcess] beat: Shutting down...
[2021-04-29 07:30:37,006: ERROR/MainProcess] consumer: Cannot connect to amqp://guest:**@127.0.0.1:5672//: [Errno 111] Connection refused.
Trying again in 2.00 seconds... (1/100)

[2021-04-29 07:30:38,951: INFO/Beat] beat: Starting...
[2021-04-29 07:30:38,973: ERROR/Beat] Removing corrupted schedule file 'celerybeat-schedule': error(11, 'Resource temporarily unavailable')
Traceback (most recent call last):
  File "/usr/local/lib/python3.7/site-packages/kombu/utils/objects.py", line 41, in __get__
    return obj.__dict__[self.__name__]
KeyError: 'scheduler'

During handling of the above exception, another exception occurred:

Traceback (most recent call last):
  File "/usr/local/lib/python3.7/site-packages/celery/beat.py", line 515, in setup_schedule
    self._store = self._open_schedule()
  File "/usr/local/lib/python3.7/site-packages/celery/beat.py", line 505, in _open_schedule
    return self.persistence.open(self.schedule_filename, writeback=True)
  File "/usr/local/lib/python3.7/shelve.py", line 243, in open
    return DbfilenameShelf(filename, flag, protocol, writeback)
  File "/usr/local/lib/python3.7/shelve.py", line 227, in __init__
    Shelf.__init__(self, dbm.open(filename, flag), protocol, writeback)
  File "/usr/local/lib/python3.7/dbm/__init__.py", line 94, in open
    return mod.open(file, flag, mode)
_gdbm.error: [Errno 11] Resource temporarily unavailable
[2021-04-29 07:30:39,018: ERROR/MainProcess] consumer: Cannot connect to amqp://guest:**@127.0.0.1:5672//: [Errno 111] Connection refused.
Trying again in 4.00 seconds... (2/100)

[2021-04-29 07:30:43,039: ERROR/MainProcess] consumer: Cannot connect to amqp://guest:**@127.0.0.1:5672//: [Errno 111] Connection refused.
Trying again in 6.00 seconds... (3/100)

[2021-04-29 07:30:49,065: ERROR/MainProcess] consumer: Cannot connect to amqp://guest:**@127.0.0.1:5672//: [Errno 111] Connection refused.
Trying again in 8.00 seconds... (4/100)

[2021-04-29 07:30:57,101: ERROR/MainProcess] consumer: Cannot connect to amqp://guest:**@127.0.0.1:5672//: [Errno 111] Connection refused.
Trying again in 10.00 seconds... (5/100)

[2021-04-29 07:31:07,118: ERROR/MainProcess] consumer: Cannot connect to amqp://guest:**@127.0.0.1:5672//: [Errno 111] Connection refused.
Trying again in 12.00 seconds... (6/100)

[2021-04-29 07:31:19,161: ERROR/MainProcess] consumer: Cannot connect to amqp://guest:**@127.0.0.1:5672//: [Errno 111] Connection refused.
Trying again in 14.00 seconds... (7/100)

[2021-04-29 07:31:33,222: ERROR/MainProcess] consumer: Cannot connect to amqp://guest:**@127.0.0.1:5672//: [Errno 111] Connection refused.
Trying again in 16.00 seconds... (8/100)

[2021-04-29 07:31:49,235: ERROR/MainProcess] consumer: Cannot connect to amqp://guest:**@127.0.0.1:5672//: [Errno 111] Connection refused.
Trying again in 18.00 seconds... (9/100)

[2021-04-29 07:32:07,249: ERROR/MainProcess] consumer: Cannot connect to amqp://guest:**@127.0.0.1:5672//: [Errno 111] Connection refused.
Trying again in 20.00 seconds... (10/100)

[2021-04-29 07:32:27,310: ERROR/MainProcess] consumer: Cannot connect to amqp://guest:**@127.0.0.1:5672//: [Errno 111] Connection refused.
Trying again in 22.00 seconds... (11/100)

[2021-04-29 07:32:49,344: ERROR/MainProcess] consumer: Cannot connect to amqp://guest:**@127.0.0.1:5672//: [Errno 111] Connection refused.
Trying again in 24.00 seconds... (12/100)

[2021-04-29 07:33:13,393: ERROR/MainProcess] consumer: Cannot connect to amqp://guest:**@127.0.0.1:5672//: [Errno 111] Connection refused.
Trying again in 26.00 seconds... (13/100)

[2021-04-29 07:33:39,438: ERROR/MainProcess] consumer: Cannot connect to amqp://guest:**@127.0.0.1:5672//: [Errno 111] Connection refused.
Trying again in 28.00 seconds... (14/100)

[2021-04-29 07:34:07,489: ERROR/MainProcess] consumer: Cannot connect to amqp://guest:**@127.0.0.1:5672//: [Errno 111] Connection refused.
Trying again in 30.00 seconds... (15/100)

[2021-04-29 07:34:37,551: ERROR/MainProcess] consumer: Cannot connect to amqp://guest:**@127.0.0.1:5672//: [Errno 111] Connection refused.
Trying again in 32.00 seconds... (16/100)

[2021-04-29 07:35:09,607: ERROR/MainProcess] consumer: Cannot connect to amqp://guest:**@127.0.0.1:5672//: [Errno 111] Connection refused.
Trying again in 32.00 seconds... (16/100)

[2021-04-29 07:35:41,668: ERROR/MainProcess] consumer: Cannot connect to amqp://guest:**@127.0.0.1:5672//: [Errno 111] Connection refused.
Trying again in 32.00 seconds... (16/100)

[2021-04-29 07:36:13,735: ERROR/MainProcess] consumer: Cannot connect to amqp://guest:**@127.0.0.1:5672//: [Errno 111] Connection refused.
Trying again in 32.00 seconds... (16/100)

[2021-04-29 07:36:45,803: ERROR/MainProcess] consumer: Cannot connect to amqp://guest:**@127.0.0.1:5672//: [Errno 111] Connection refused.
Trying again in 32.00 seconds... (16/100)

[2021-04-29 07:37:17,876: ERROR/MainProcess] consumer: Cannot connect to amqp://guest:**@127.0.0.1:5672//: [Errno 111] Connection refused.
Trying again in 32.00 seconds... (16/100)

[2021-04-29 07:37:49,941: ERROR/MainProcess] consumer: Cannot connect to amqp://guest:**@127.0.0.1:5672//: [Errno 111] Connection refused.
Trying again in 32.00 seconds... (16/100)

[2021-04-29 07:38:21,995: ERROR/MainProcess] consumer: Cannot connect to amqp://guest:**@127.0.0.1:5672//: [Errno 111] Connection refused.
Trying again in 32.00 seconds... (16/100)

[2021-04-29 07:38:54,051: ERROR/MainProcess] consumer: Cannot connect to amqp://guest:**@127.0.0.1:5672//: [Errno 111] Connection refused.
Trying again in 32.00 seconds... (16/100)

[2021-04-29 07:39:26,111: ERROR/MainProcess] consumer: Cannot connect to amqp://guest:**@127.0.0.1:5672//: [Errno 111] Connection refused.
Trying again in 32.00 seconds... (16/100)

[2021-04-29 07:39:58,166: ERROR/MainProcess] consumer: Cannot connect to amqp://guest:**@127.0.0.1:5672//: [Errno 111] Connection refused.
Trying again in 32.00 seconds... (16/100)

[2021-04-29 07:40:30,216: ERROR/MainProcess] consumer: Cannot connect to amqp://guest:**@127.0.0.1:5672//: [Errno 111] Connection refused.
Trying again in 32.00 seconds... (16/100)

[2021-04-29 07:41:02,279: ERROR/MainProcess] consumer: Cannot connect to amqp://guest:**@127.0.0.1:5672//: [Errno 111] Connection refused.
Trying again in 32.00 seconds... (16/100)

[2021-04-29 07:41:34,359: ERROR/MainProcess] consumer: Cannot connect to amqp://guest:**@127.0.0.1:5672//: [Errno 111] Connection refused.
Trying again in 32.00 seconds... (16/100)

[2021-04-29 07:42:06,416: ERROR/MainProcess] consumer: Cannot connect to amqp://guest:**@127.0.0.1:5672//: [Errno 111] Connection refused.
Trying again in 32.00 seconds... (16/100)

[2021-04-29 07:42:38,481: ERROR/MainProcess] consumer: Cannot connect to amqp://guest:**@127.0.0.1:5672//: [Errno 111] Connection refused.
Trying again in 32.00 seconds... (16/100)

[2021-04-29 07:43:10,541: ERROR/MainProcess] consumer: Cannot connect to amqp://guest:**@127.0.0.1:5672//: [Errno 111] Connection refused.
Trying again in 32.00 seconds... (16/100)

[2021-04-29 07:43:42,607: ERROR/MainProcess] consumer: Cannot connect to amqp://guest:**@127.0.0.1:5672//: [Errno 111] Connection refused.
Trying again in 32.00 seconds... (16/100)

[2021-04-29 07:44:14,662: ERROR/MainProcess] consumer: Cannot connect to amqp://guest:**@127.0.0.1:5672//: [Errno 111] Connection refused.
Trying again in 32.00 seconds... (16/100)

[2021-04-29 07:44:46,748: ERROR/MainProcess] consumer: Cannot connect to amqp://guest:**@127.0.0.1:5672//: [Errno 111] Connection refused.
Trying again in 32.00 seconds... (16/100)

[2021-04-29 07:45:18,818: ERROR/MainProcess] consumer: Cannot connect to amqp://guest:**@127.0.0.1:5672//: [Errno 111] Connection refused.
Trying again in 32.00 seconds... (16/100)

[2021-04-29 07:45:50,876: ERROR/MainProcess] consumer: Cannot connect to amqp://guest:**@127.0.0.1:5672//: [Errno 111] Connection refused.
Trying again in 32.00 seconds... (16/100)

[2021-04-29 07:46:22,943: ERROR/MainProcess] consumer: Cannot connect to amqp://guest:**@127.0.0.1:5672//: [Errno 111] Connection refused.
Trying again in 32.00 seconds... (16/100)

[2021-04-29 07:46:55,008: ERROR/MainProcess] consumer: Cannot connect to amqp://guest:**@127.0.0.1:5672//: [Errno 111] Connection refused.
Trying again in 32.00 seconds... (16/100)

[2021-04-29 07:47:27,076: ERROR/MainProcess] consumer: Cannot connect to amqp://guest:**@127.0.0.1:5672//: [Errno 111] Connection refused.
Trying again in 32.00 seconds... (16/100)

[2021-04-29 07:47:59,135: ERROR/MainProcess] consumer: Cannot connect to amqp://guest:**@127.0.0.1:5672//: [Errno 111] Connection refused.
Trying again in 32.00 seconds... (16/100)

[2021-04-29 07:48:31,197: ERROR/MainProcess] consumer: Cannot connect to amqp://guest:**@127.0.0.1:5672//: [Errno 111] Connection refused.
Trying again in 32.00 seconds... (16/100)

[2021-04-29 07:49:03,251: ERROR/MainProcess] consumer: Cannot connect to amqp://guest:**@127.0.0.1:5672//: [Errno 111] Connection refused.
Trying again in 32.00 seconds... (16/100)

[2021-04-29 07:49:35,294: ERROR/MainProcess] consumer: Cannot connect to amqp://guest:**@127.0.0.1:5672//: [Errno 111] Connection refused.
Trying again in 32.00 seconds... (16/100)

[2021-04-29 07:50:07,344: ERROR/MainProcess] consumer: Cannot connect to amqp://guest:**@127.0.0.1:5672//: [Errno 111] Connection refused.
Trying again in 32.00 seconds... (16/100)

[2021-04-29 07:50:39,398: ERROR/MainProcess] consumer: Cannot connect to amqp://guest:**@127.0.0.1:5672//: [Errno 111] Connection refused.
Trying again in 32.00 seconds... (16/100)

[2021-04-29 07:51:11,446: ERROR/MainProcess] consumer: Cannot connect to amqp://guest:**@127.0.0.1:5672//: [Errno 111] Connection refused.
Trying again in 32.00 seconds... (16/100)

[2021-04-29 07:51:43,666: ERROR/MainProcess] consumer: Cannot connect to amqp://guest:**@127.0.0.1:5672//: [Errno 111] Connection refused.
Trying again in 32.00 seconds... (16/100)

[2021-04-29 07:52:15,734: ERROR/MainProcess] consumer: Cannot connect to amqp://guest:**@127.0.0.1:5672//: [Errno 111] Connection refused.
Trying again in 32.00 seconds... (16/100)

[2021-04-29 07:52:47,808: ERROR/MainProcess] consumer: Cannot connect to amqp://guest:**@127.0.0.1:5672//: [Errno 111] Connection refused.
Trying again in 32.00 seconds... (16/100)

[2021-04-29 07:53:19,863: ERROR/MainProcess] consumer: Cannot connect to amqp://guest:**@127.0.0.1:5672//: [Errno 111] Connection refused.
Trying again in 32.00 seconds... (16/100)

[2021-04-29 07:53:51,918: ERROR/MainProcess] consumer: Cannot connect to amqp://guest:**@127.0.0.1:5672//: [Errno 111] Connection refused.
Trying again in 32.00 seconds... (16/100)

[2021-04-29 07:54:23,960: ERROR/MainProcess] consumer: Cannot connect to amqp://guest:**@127.0.0.1:5672//: [Errno 111] Connection refused.
Trying again in 32.00 seconds... (16/100)

[2021-04-29 07:54:55,990: ERROR/MainProcess] consumer: Cannot connect to amqp://guest:**@127.0.0.1:5672//: [Errno 111] Connection refused.
Trying again in 32.00 seconds... (16/100)

[2021-04-29 07:55:28,049: ERROR/MainProcess] consumer: Cannot connect to amqp://guest:**@127.0.0.1:5672//: [Errno 111] Connection refused.
Trying again in 32.00 seconds... (16/100)

[2021-04-29 07:56:00,107: ERROR/MainProcess] consumer: Cannot connect to amqp://guest:**@127.0.0.1:5672//: [Errno 111] Connection refused.
Trying again in 32.00 seconds... (16/100)

[2021-04-29 07:56:32,164: ERROR/MainProcess] consumer: Cannot connect to amqp://guest:**@127.0.0.1:5672//: [Errno 111] Connection refused.
Trying again in 32.00 seconds... (16/100)

[2021-04-29 07:57:04,204: ERROR/MainProcess] consumer: Cannot connect to amqp://guest:**@127.0.0.1:5672//: [Errno 111] Connection refused.
Trying again in 32.00 seconds... (16/100)

[2021-04-29 07:57:36,252: ERROR/MainProcess] consumer: Cannot connect to amqp://guest:**@127.0.0.1:5672//: [Errno 111] Connection refused.
Trying again in 32.00 seconds... (16/100)

[2021-04-29 07:58:08,321: ERROR/MainProcess] consumer: Cannot connect to amqp://guest:**@127.0.0.1:5672//: [Errno 111] Connection refused.
Trying again in 32.00 seconds... (16/100)

[2021-04-29 07:58:29,747: INFO/MainProcess] beat: Shutting down...
[2021-04-29 08:05:29,698: ERROR/MainProcess] consumer: Cannot connect to amqp://guest:**@127.0.0.1:5672//: [Errno 111] Connection refused.
Trying again in 2.00 seconds... (1/100)

[2021-04-29 08:05:31,710: ERROR/MainProcess] consumer: Cannot connect to amqp://guest:**@127.0.0.1:5672//: [Errno 111] Connection refused.
Trying again in 4.00 seconds... (2/100)

[2021-04-29 08:05:32,021: INFO/Beat] beat: Starting...
[2021-04-29 08:05:32,043: ERROR/Beat] Removing corrupted schedule file 'celerybeat-schedule': error(11, 'Resource temporarily unavailable')
Traceback (most recent call last):
  File "/usr/local/lib/python3.7/site-packages/kombu/utils/objects.py", line 41, in __get__
    return obj.__dict__[self.__name__]
KeyError: 'scheduler'

During handling of the above exception, another exception occurred:

Traceback (most recent call last):
  File "/usr/local/lib/python3.7/site-packages/celery/beat.py", line 515, in setup_schedule
    self._store = self._open_schedule()
  File "/usr/local/lib/python3.7/site-packages/celery/beat.py", line 505, in _open_schedule
    return self.persistence.open(self.schedule_filename, writeback=True)
  File "/usr/local/lib/python3.7/shelve.py", line 243, in open
    return DbfilenameShelf(filename, flag, protocol, writeback)
  File "/usr/local/lib/python3.7/shelve.py", line 227, in __init__
    Shelf.__init__(self, dbm.open(filename, flag), protocol, writeback)
  File "/usr/local/lib/python3.7/dbm/__init__.py", line 94, in open
    return mod.open(file, flag, mode)
_gdbm.error: [Errno 11] Resource temporarily unavailable
[2021-04-29 08:05:35,694: ERROR/MainProcess] consumer: Cannot connect to amqp://guest:**@127.0.0.1:5672//: [Errno 111] Connection refused.
Trying again in 6.00 seconds... (3/100)

[2021-04-29 08:05:41,726: ERROR/MainProcess] consumer: Cannot connect to amqp://guest:**@127.0.0.1:5672//: [Errno 111] Connection refused.
Trying again in 8.00 seconds... (4/100)

[2021-04-29 08:05:49,753: ERROR/MainProcess] consumer: Cannot connect to amqp://guest:**@127.0.0.1:5672//: [Errno 111] Connection refused.
Trying again in 10.00 seconds... (5/100)

[2021-04-29 08:05:59,790: ERROR/MainProcess] consumer: Cannot connect to amqp://guest:**@127.0.0.1:5672//: [Errno 111] Connection refused.
Trying again in 12.00 seconds... (6/100)

[2021-04-29 08:06:11,799: ERROR/MainProcess] consumer: Cannot connect to amqp://guest:**@127.0.0.1:5672//: [Errno 111] Connection refused.
Trying again in 14.00 seconds... (7/100)

[2021-04-29 08:06:25,844: ERROR/MainProcess] consumer: Cannot connect to amqp://guest:**@127.0.0.1:5672//: [Errno 111] Connection refused.
Trying again in 16.00 seconds... (8/100)

[2021-04-29 08:06:41,865: ERROR/MainProcess] consumer: Cannot connect to amqp://guest:**@127.0.0.1:5672//: [Errno 111] Connection refused.
Trying again in 18.00 seconds... (9/100)

[2021-04-29 08:06:59,911: ERROR/MainProcess] consumer: Cannot connect to amqp://guest:**@127.0.0.1:5672//: [Errno 111] Connection refused.
Trying again in 20.00 seconds... (10/100)

[2021-04-29 08:07:19,927: ERROR/MainProcess] consumer: Cannot connect to amqp://guest:**@127.0.0.1:5672//: [Errno 111] Connection refused.
Trying again in 22.00 seconds... (11/100)

[2021-04-29 08:07:41,952: ERROR/MainProcess] consumer: Cannot connect to amqp://guest:**@127.0.0.1:5672//: [Errno 111] Connection refused.
Trying again in 24.00 seconds... (12/100)

[2021-04-29 08:08:06,002: ERROR/MainProcess] consumer: Cannot connect to amqp://guest:**@127.0.0.1:5672//: [Errno 111] Connection refused.
Trying again in 26.00 seconds... (13/100)

[2021-04-29 08:08:32,078: ERROR/MainProcess] consumer: Cannot connect to amqp://guest:**@127.0.0.1:5672//: [Errno 111] Connection refused.
Trying again in 28.00 seconds... (14/100)

[2021-04-29 08:09:00,119: ERROR/MainProcess] consumer: Cannot connect to amqp://guest:**@127.0.0.1:5672//: [Errno 111] Connection refused.
Trying again in 30.00 seconds... (15/100)

[2021-04-29 08:09:30,162: ERROR/MainProcess] consumer: Cannot connect to amqp://guest:**@127.0.0.1:5672//: [Errno 111] Connection refused.
Trying again in 32.00 seconds... (16/100)

[2021-04-29 08:10:02,206: ERROR/MainProcess] consumer: Cannot connect to amqp://guest:**@127.0.0.1:5672//: [Errno 111] Connection refused.
Trying again in 32.00 seconds... (16/100)

[2021-04-29 08:10:34,232: ERROR/MainProcess] consumer: Cannot connect to amqp://guest:**@127.0.0.1:5672//: [Errno 111] Connection refused.
Trying again in 32.00 seconds... (16/100)

[2021-04-29 08:11:06,283: ERROR/MainProcess] consumer: Cannot connect to amqp://guest:**@127.0.0.1:5672//: [Errno 111] Connection refused.
Trying again in 32.00 seconds... (16/100)

[2021-04-29 08:11:38,342: ERROR/MainProcess] consumer: Cannot connect to amqp://guest:**@127.0.0.1:5672//: [Errno 111] Connection refused.
Trying again in 32.00 seconds... (16/100)

[2021-04-29 08:12:10,404: ERROR/MainProcess] consumer: Cannot connect to amqp://guest:**@127.0.0.1:5672//: [Errno 111] Connection refused.
Trying again in 32.00 seconds... (16/100)

[2021-04-29 08:12:42,475: ERROR/MainProcess] consumer: Cannot connect to amqp://guest:**@127.0.0.1:5672//: [Errno 111] Connection refused.
Trying again in 32.00 seconds... (16/100)

[2021-04-29 08:13:14,540: ERROR/MainProcess] consumer: Cannot connect to amqp://guest:**@127.0.0.1:5672//: [Errno 111] Connection refused.
Trying again in 32.00 seconds... (16/100)

[2021-04-29 08:13:46,600: ERROR/MainProcess] consumer: Cannot connect to amqp://guest:**@127.0.0.1:5672//: [Errno 111] Connection refused.
Trying again in 32.00 seconds... (16/100)

[2021-04-29 08:14:18,649: ERROR/MainProcess] consumer: Cannot connect to amqp://guest:**@127.0.0.1:5672//: [Errno 111] Connection refused.
Trying again in 32.00 seconds... (16/100)

[2021-04-29 08:14:50,708: ERROR/MainProcess] consumer: Cannot connect to amqp://guest:**@127.0.0.1:5672//: [Errno 111] Connection refused.
Trying again in 32.00 seconds... (16/100)

[2021-04-29 08:15:22,771: ERROR/MainProcess] consumer: Cannot connect to amqp://guest:**@127.0.0.1:5672//: [Errno 111] Connection refused.
Trying again in 32.00 seconds... (16/100)

[2021-04-29 08:15:54,811: ERROR/MainProcess] consumer: Cannot connect to amqp://guest:**@127.0.0.1:5672//: [Errno 111] Connection refused.
Trying again in 32.00 seconds... (16/100)

[2021-04-29 08:16:26,877: ERROR/MainProcess] consumer: Cannot connect to amqp://guest:**@127.0.0.1:5672//: [Errno 111] Connection refused.
Trying again in 32.00 seconds... (16/100)

[2021-04-29 08:16:58,953: ERROR/MainProcess] consumer: Cannot connect to amqp://guest:**@127.0.0.1:5672//: [Errno 111] Connection refused.
Trying again in 32.00 seconds... (16/100)

[2021-04-29 08:17:31,018: ERROR/MainProcess] consumer: Cannot connect to amqp://guest:**@127.0.0.1:5672//: [Errno 111] Connection refused.
Trying again in 32.00 seconds... (16/100)

[2021-04-29 08:18:03,081: ERROR/MainProcess] consumer: Cannot connect to amqp://guest:**@127.0.0.1:5672//: [Errno 111] Connection refused.
Trying again in 32.00 seconds... (16/100)

[2021-04-29 08:18:35,101: ERROR/MainProcess] consumer: Cannot connect to amqp://guest:**@127.0.0.1:5672//: [Errno 111] Connection refused.
Trying again in 32.00 seconds... (16/100)

[2021-04-29 08:19:07,169: ERROR/MainProcess] consumer: Cannot connect to amqp://guest:**@127.0.0.1:5672//: [Errno 111] Connection refused.
Trying again in 32.00 seconds... (16/100)

[2021-04-29 08:19:21,943: INFO/MainProcess] beat: Shutting down...
[2021-04-29 08:23:05,527: ERROR/MainProcess] consumer: Cannot connect to amqp://guest:**@127.0.0.1:5672//: [Errno 111] Connection refused.
Trying again in 2.00 seconds... (1/100)

[2021-04-29 08:23:07,521: INFO/Beat] beat: Starting...
[2021-04-29 08:23:07,537: ERROR/MainProcess] consumer: Cannot connect to amqp://guest:**@127.0.0.1:5672//: [Errno 111] Connection refused.
Trying again in 4.00 seconds... (2/100)

[2021-04-29 08:23:07,541: ERROR/Beat] Removing corrupted schedule file 'celerybeat-schedule': error(11, 'Resource temporarily unavailable')
Traceback (most recent call last):
  File "/usr/local/lib/python3.7/site-packages/kombu/utils/objects.py", line 41, in __get__
    return obj.__dict__[self.__name__]
KeyError: 'scheduler'

During handling of the above exception, another exception occurred:

Traceback (most recent call last):
  File "/usr/local/lib/python3.7/site-packages/celery/beat.py", line 515, in setup_schedule
    self._store = self._open_schedule()
  File "/usr/local/lib/python3.7/site-packages/celery/beat.py", line 505, in _open_schedule
    return self.persistence.open(self.schedule_filename, writeback=True)
  File "/usr/local/lib/python3.7/shelve.py", line 243, in open
    return DbfilenameShelf(filename, flag, protocol, writeback)
  File "/usr/local/lib/python3.7/shelve.py", line 227, in __init__
    Shelf.__init__(self, dbm.open(filename, flag), protocol, writeback)
  File "/usr/local/lib/python3.7/dbm/__init__.py", line 94, in open
    return mod.open(file, flag, mode)
_gdbm.error: [Errno 11] Resource temporarily unavailable
[2021-04-29 08:23:11,557: ERROR/MainProcess] consumer: Cannot connect to amqp://guest:**@127.0.0.1:5672//: [Errno 111] Connection refused.
Trying again in 6.00 seconds... (3/100)

[2021-04-29 08:23:17,577: ERROR/MainProcess] consumer: Cannot connect to amqp://guest:**@127.0.0.1:5672//: [Errno 111] Connection refused.
Trying again in 8.00 seconds... (4/100)

[2021-04-29 08:23:25,604: ERROR/MainProcess] consumer: Cannot connect to amqp://guest:**@127.0.0.1:5672//: [Errno 111] Connection refused.
Trying again in 10.00 seconds... (5/100)

[2021-04-29 08:23:35,604: ERROR/MainProcess] consumer: Cannot connect to amqp://guest:**@127.0.0.1:5672//: [Errno 111] Connection refused.
Trying again in 12.00 seconds... (6/100)

[2021-04-29 08:23:47,652: ERROR/MainProcess] consumer: Cannot connect to amqp://guest:**@127.0.0.1:5672//: [Errno 111] Connection refused.
Trying again in 14.00 seconds... (7/100)

[2021-04-29 08:24:01,707: ERROR/MainProcess] consumer: Cannot connect to amqp://guest:**@127.0.0.1:5672//: [Errno 111] Connection refused.
Trying again in 16.00 seconds... (8/100)

[2021-04-29 08:24:17,729: ERROR/MainProcess] consumer: Cannot connect to amqp://guest:**@127.0.0.1:5672//: [Errno 111] Connection refused.
Trying again in 18.00 seconds... (9/100)

[2021-04-29 08:24:35,754: ERROR/MainProcess] consumer: Cannot connect to amqp://guest:**@127.0.0.1:5672//: [Errno 111] Connection refused.
Trying again in 20.00 seconds... (10/100)

[2021-04-29 08:24:55,822: ERROR/MainProcess] consumer: Cannot connect to amqp://guest:**@127.0.0.1:5672//: [Errno 111] Connection refused.
Trying again in 22.00 seconds... (11/100)

[2021-04-29 08:25:17,851: ERROR/MainProcess] consumer: Cannot connect to amqp://guest:**@127.0.0.1:5672//: [Errno 111] Connection refused.
Trying again in 24.00 seconds... (12/100)

[2021-04-29 08:25:41,906: ERROR/MainProcess] consumer: Cannot connect to amqp://guest:**@127.0.0.1:5672//: [Errno 111] Connection refused.
Trying again in 26.00 seconds... (13/100)

[2021-04-29 08:26:07,970: ERROR/MainProcess] consumer: Cannot connect to amqp://guest:**@127.0.0.1:5672//: [Errno 111] Connection refused.
Trying again in 28.00 seconds... (14/100)

[2021-04-29 08:26:36,020: ERROR/MainProcess] consumer: Cannot connect to amqp://guest:**@127.0.0.1:5672//: [Errno 111] Connection refused.
Trying again in 30.00 seconds... (15/100)

[2021-04-29 08:27:06,080: ERROR/MainProcess] consumer: Cannot connect to amqp://guest:**@127.0.0.1:5672//: [Errno 111] Connection refused.
Trying again in 32.00 seconds... (16/100)

