[2021-05-02 08:48:49,369: INFO/MainProcess] Connected to redis://redis:6379//
[2021-05-02 08:48:49,386: INFO/MainProcess] mingle: searching for neighbors
[2021-05-02 08:48:50,415: INFO/MainProcess] mingle: all alone
[2021-05-02 08:48:50,434: WARNING/MainProcess] /usr/local/lib/python3.7/site-packages/celery/fixups/django.py:204: UserWarning: Using settings.DEBUG leads to a memory
            leak, never use this setting in production environments!
  leak, never use this setting in production environments!''')

[2021-05-02 08:48:50,436: INFO/MainProcess] celery@bd3af76b5771 ready.
[2021-05-02 08:48:51,509: INFO/Beat] beat: Starting...
[2021-05-02 08:49:15,927: INFO/MainProcess] beat: Shutting down...
[2021-05-02 09:35:08,496: INFO/MainProcess] Connected to redis://redis:6379//
[2021-05-02 09:35:08,508: INFO/MainProcess] mingle: searching for neighbors
[2021-05-02 09:35:09,537: INFO/MainProcess] mingle: all alone
[2021-05-02 09:35:09,558: WARNING/MainProcess] /usr/local/lib/python3.7/site-packages/celery/fixups/django.py:204: UserWarning: Using settings.DEBUG leads to a memory
            leak, never use this setting in production environments!
  leak, never use this setting in production environments!''')

[2021-05-02 09:35:09,560: INFO/MainProcess] celery@bd3af76b5771 ready.
[2021-05-02 09:35:10,779: INFO/Beat] beat: Starting...
[2021-05-02 09:48:35,742: INFO/MainProcess] beat: Shutting down...
[2021-05-02 09:49:06,532: INFO/MainProcess] Connected to redis://redis:6379//
[2021-05-02 09:49:06,544: INFO/MainProcess] mingle: searching for neighbors
[2021-05-02 09:49:07,571: INFO/MainProcess] mingle: all alone
[2021-05-02 09:49:07,593: WARNING/MainProcess] /usr/local/lib/python3.7/site-packages/celery/fixups/django.py:204: UserWarning: Using settings.DEBUG leads to a memory
            leak, never use this setting in production environments!
  leak, never use this setting in production environments!''')

[2021-05-02 09:49:07,596: INFO/MainProcess] celery@c452f552cb31 ready.
[2021-05-02 09:49:08,725: INFO/Beat] beat: Starting...
[2021-05-02 10:02:52,960: INFO/MainProcess] beat: Shutting down...
[2021-05-02 10:50:43,089: INFO/MainProcess] Connected to redis://redis:6379//
[2021-05-02 10:50:43,101: INFO/MainProcess] mingle: searching for neighbors
[2021-05-02 10:50:44,129: INFO/MainProcess] mingle: all alone
[2021-05-02 10:50:44,154: WARNING/MainProcess] /usr/local/lib/python3.7/site-packages/celery/fixups/django.py:204: UserWarning: Using settings.DEBUG leads to a memory
            leak, never use this setting in production environments!
  leak, never use this setting in production environments!''')

[2021-05-02 10:50:44,156: INFO/MainProcess] celery@c452f552cb31 ready.
[2021-05-02 10:50:45,032: INFO/Beat] beat: Starting...
[2021-05-02 10:51:54,156: INFO/MainProcess] Received task: create_csv[84937392-28ef-4dd5-9b5c-9d0d1341436a]  
[2021-05-02 10:51:54,205: INFO/ForkPoolWorker-4] Task create_csv[84937392-28ef-4dd5-9b5c-9d0d1341436a] succeeded in 0.04315720000886358s: ('1_2021-05-02T10:51:54.176648Z.csv', '2021-05-02T10:51:54.176648Z')
[2021-05-02 10:52:03,545: INFO/MainProcess] Received task: create_csv[8cb6f601-0292-4ece-874a-e9c9d9b277a9]  
[2021-05-02 10:52:03,571: INFO/ForkPoolWorker-4] Task create_csv[8cb6f601-0292-4ece-874a-e9c9d9b277a9] succeeded in 0.022181700012879446s: ('1_2021-05-02T10:52:03.557605Z.csv', '2021-05-02T10:52:03.557605Z')
[2021-05-02 13:12:02,483: INFO/MainProcess] Received task: create_csv[fc19dec0-ba79-4a4b-817e-c77b26f2b618]  
[2021-05-02 13:12:02,521: INFO/ForkPoolWorker-4] Task create_csv[fc19dec0-ba79-4a4b-817e-c77b26f2b618] succeeded in 0.030932599998777732s: ('1_2021-05-02T13:12:02.501840Z.csv', '2021-05-02T13:12:02.501840Z')
[2021-05-02 13:12:28,529: INFO/MainProcess] Received task: create_csv[6a3faff4-51fa-4143-98c2-ba0f05b1caae]  
[2021-05-02 13:12:28,554: INFO/ForkPoolWorker-4] Task create_csv[6a3faff4-51fa-4143-98c2-ba0f05b1caae] succeeded in 0.021192199987126514s: ('1_2021-05-02T13:12:28.539320Z.csv', '2021-05-02T13:12:28.539320Z')
[2021-05-02 13:18:31,453: INFO/MainProcess] Received task: create_csv[8fc266f3-91be-4659-9b9e-a86168ad3da0]  
[2021-05-02 13:18:31,480: INFO/ForkPoolWorker-4] Task create_csv[8fc266f3-91be-4659-9b9e-a86168ad3da0] succeeded in 0.023226700024679303s: ('1_2021-05-02T13:18:31.463760Z.csv', '2021-05-02T13:18:31.463760Z')
[2021-05-02 13:20:37,831: INFO/MainProcess] Received task: create_csv[e5142dc0-aedf-437f-bb25-fd59d54af4f7]  
[2021-05-02 13:20:37,861: ERROR/ForkPoolWorker-4] Task create_csv[e5142dc0-aedf-437f-bb25-fd59d54af4f7] raised unexpected: TypeError("'str' object cannot be interpreted as an integer")
Traceback (most recent call last):
  File "/usr/local/lib/python3.7/site-packages/celery/app/trace.py", line 405, in trace_task
    R = retval = fun(*args, **kwargs)
  File "/usr/local/lib/python3.7/site-packages/celery/app/trace.py", line 697, in __protected_call__
    return self.run(*args, **kwargs)
  File "/usr/src/app/FakeCsvApp/tasks.py", line 50, in create_csv_task
    for row in range(row_num):
TypeError: 'str' object cannot be interpreted as an integer
[2021-05-02 14:41:48,635: INFO/MainProcess] Received task: create_csv[d68f60a8-0179-469f-8ce5-a596114d8f3c]  
[2021-05-02 14:41:48,666: INFO/ForkPoolWorker-4] Task create_csv[d68f60a8-0179-469f-8ce5-a596114d8f3c] succeeded in 0.026488800009246916s: ('1_2021-05-02T14:41:48.648124Z.csv', '2021-05-02T14:41:48.648124Z')
[2021-05-02 14:49:52,013: INFO/MainProcess] Received task: create_csv[72d651dc-a740-4b76-9123-e3f222194736]  
[2021-05-02 14:49:52,035: INFO/ForkPoolWorker-4] Task create_csv[72d651dc-a740-4b76-9123-e3f222194736] succeeded in 0.01784570000017993s: ('2_2021-05-02T14:49:52.024031Z.csv', '2021-05-02T14:49:52.024031Z')
[2021-05-02 14:51:17,500: INFO/MainProcess] Received task: create_csv[cdf7ace4-9f4c-4d46-bebc-a3fd0e10781b]  
[2021-05-02 14:51:17,525: INFO/ForkPoolWorker-4] Task create_csv[cdf7ace4-9f4c-4d46-bebc-a3fd0e10781b] succeeded in 0.02102089999243617s: ('2_2021-05-02T14:51:17.510593Z.csv', '2021-05-02T14:51:17.510593Z')
[2021-05-02 16:12:51,229: INFO/MainProcess] Received task: create_csv[31c57c5e-0ec8-4c40-9514-da0fd90ef219]  
[2021-05-02 16:12:51,254: INFO/ForkPoolWorker-4] Task create_csv[31c57c5e-0ec8-4c40-9514-da0fd90ef219] succeeded in 0.021402600017609075s: ('3_2021-05-02T16:12:51.241780Z.csv', '2021-05-02T16:12:51.241780Z')
[2021-05-02 16:15:09,204: INFO/MainProcess] Received task: create_csv[c9830a9c-9a19-4284-ad4d-c119a6687492]  
[2021-05-02 16:15:09,227: INFO/ForkPoolWorker-4] Task create_csv[c9830a9c-9a19-4284-ad4d-c119a6687492] succeeded in 0.020008399995276704s: ('3_2021-05-02T16:15:09.213549Z.csv', '2021-05-02T16:15:09.213549Z')
[2021-05-02 16:22:28,185: INFO/MainProcess] beat: Shutting down...
[2021-05-02 16:22:35,628: INFO/MainProcess] Connected to redis://redis:6379//
[2021-05-02 16:22:35,645: INFO/MainProcess] mingle: searching for neighbors
[2021-05-02 16:22:36,673: INFO/MainProcess] mingle: all alone
[2021-05-02 16:22:36,696: WARNING/MainProcess] /usr/local/lib/python3.7/site-packages/celery/fixups/django.py:204: UserWarning: Using settings.DEBUG leads to a memory
            leak, never use this setting in production environments!
  leak, never use this setting in production environments!''')

[2021-05-02 16:22:36,699: INFO/MainProcess] celery@c452f552cb31 ready.
[2021-05-02 16:22:37,587: INFO/Beat] beat: Starting...
[2021-05-03 01:44:24,908: INFO/MainProcess] Received task: create_csv[7977f08d-86ca-4ef6-8a01-0475f5fdb650]  
[2021-05-03 01:44:24,956: INFO/ForkPoolWorker-4] Task create_csv[7977f08d-86ca-4ef6-8a01-0475f5fdb650] succeeded in 0.04261199999018572s: ('3_2021-05-03T01:44:24.926755Z.csv', '2021-05-03T01:44:24.926755Z')
[2021-05-03 01:44:54,156: INFO/MainProcess] Received task: create_csv[dd9a9db2-247d-4068-a19d-35f0fee9a328]  
[2021-05-03 01:44:54,182: INFO/ForkPoolWorker-4] Task create_csv[dd9a9db2-247d-4068-a19d-35f0fee9a328] succeeded in 0.02286109997658059s: ('3_2021-05-03T01:44:54.167592Z.csv', '2021-05-03T01:44:54.167592Z')
[2021-05-03 01:44:58,509: INFO/MainProcess] Received task: create_csv[0470973f-7982-4dd3-959c-6ea12d3e11d2]  
[2021-05-03 01:44:58,535: INFO/ForkPoolWorker-4] Task create_csv[0470973f-7982-4dd3-959c-6ea12d3e11d2] succeeded in 0.022481000021798536s: ('3_2021-05-03T01:44:58.519512Z.csv', '2021-05-03T01:44:58.519512Z')
[2021-05-03 01:54:29,352: INFO/MainProcess] Received task: create_csv[e1bae3b7-40a7-4ec2-83c5-c27d9d050664]  
[2021-05-03 01:54:29,379: INFO/ForkPoolWorker-4] Task create_csv[e1bae3b7-40a7-4ec2-83c5-c27d9d050664] succeeded in 0.0214241000066977s: ('2_2021-05-03T01:54:29.364462Z.csv', '2021-05-03T01:54:29.364462Z')
[2021-05-04 15:24:02,408: INFO/MainProcess] Connected to redis://redis:6379//
[2021-05-04 15:24:02,422: INFO/MainProcess] mingle: searching for neighbors
[2021-05-04 15:24:03,413: INFO/MainProcess] mingle: all alone
[2021-05-04 15:24:03,432: WARNING/MainProcess] /usr/local/lib/python3.7/site-packages/celery/fixups/django.py:204: UserWarning: Using settings.DEBUG leads to a memory
            leak, never use this setting in production environments!
  leak, never use this setting in production environments!''')

[2021-05-04 15:24:03,435: INFO/MainProcess] celery@5bad0d8b5e2d ready.
[2021-05-04 15:24:04,249: INFO/Beat] beat: Starting...
[2021-05-04 15:26:46,680: INFO/MainProcess] Received task: create_csv[22cf39d6-ba39-41eb-9156-cffeb489505e]  
[2021-05-04 15:26:46,711: ERROR/ForkPoolWorker-4] Task create_csv[22cf39d6-ba39-41eb-9156-cffeb489505e] raised unexpected: ProgrammingError('column FakeCsvApp_schemas.ColumnSeparator does not exist\nLINE 1: ..._schemas"."User_id", "FakeCsvApp_schemas"."Name", "FakeCsvAp...\n                                                             ^\n')
Traceback (most recent call last):
  File "/usr/local/lib/python3.7/site-packages/django/db/backends/utils.py", line 84, in _execute
    return self.cursor.execute(sql, params)
psycopg2.errors.UndefinedColumn: column FakeCsvApp_schemas.ColumnSeparator does not exist
LINE 1: ..._schemas"."User_id", "FakeCsvApp_schemas"."Name", "FakeCsvAp...
                                                             ^


The above exception was the direct cause of the following exception:

Traceback (most recent call last):
  File "/usr/local/lib/python3.7/site-packages/celery/app/trace.py", line 405, in trace_task
    R = retval = fun(*args, **kwargs)
  File "/usr/local/lib/python3.7/site-packages/celery/app/trace.py", line 697, in __protected_call__
    return self.run(*args, **kwargs)
  File "/usr/src/app/FakeCsvApp/tasks.py", line 44, in create_csv_task
    column_name, column_type, column_from, column_to, schema_date_modified = prepare_data(schema_id)
  File "/usr/src/app/FakeCsvApp/tasks.py", line 19, in prepare_data
    schema = Schemas.objects.get(id=schema_id)
  File "/usr/local/lib/python3.7/site-packages/django/db/models/manager.py", line 85, in manager_method
    return getattr(self.get_queryset(), name)(*args, **kwargs)
  File "/usr/local/lib/python3.7/site-packages/django/db/models/query.py", line 431, in get
    num = len(clone)
  File "/usr/local/lib/python3.7/site-packages/django/db/models/query.py", line 262, in __len__
    self._fetch_all()
  File "/usr/local/lib/python3.7/site-packages/django/db/models/query.py", line 1324, in _fetch_all
    self._result_cache = list(self._iterable_class(self))
  File "/usr/local/lib/python3.7/site-packages/django/db/models/query.py", line 51, in __iter__
    results = compiler.execute_sql(chunked_fetch=self.chunked_fetch, chunk_size=self.chunk_size)
  File "/usr/local/lib/python3.7/site-packages/django/db/models/sql/compiler.py", line 1169, in execute_sql
    cursor.execute(sql, params)
  File "/usr/local/lib/python3.7/site-packages/django/db/backends/utils.py", line 98, in execute
    return super().execute(sql, params)
  File "/usr/local/lib/python3.7/site-packages/django/db/backends/utils.py", line 66, in execute
    return self._execute_with_wrappers(sql, params, many=False, executor=self._execute)
  File "/usr/local/lib/python3.7/site-packages/django/db/backends/utils.py", line 75, in _execute_with_wrappers
    return executor(sql, params, many, context)
  File "/usr/local/lib/python3.7/site-packages/django/db/backends/utils.py", line 84, in _execute
    return self.cursor.execute(sql, params)
  File "/usr/local/lib/python3.7/site-packages/django/db/utils.py", line 90, in __exit__
    raise dj_exc_value.with_traceback(traceback) from exc_value
  File "/usr/local/lib/python3.7/site-packages/django/db/backends/utils.py", line 84, in _execute
    return self.cursor.execute(sql, params)
django.db.utils.ProgrammingError: column FakeCsvApp_schemas.ColumnSeparator does not exist
LINE 1: ..._schemas"."User_id", "FakeCsvApp_schemas"."Name", "FakeCsvAp...
                                                             ^

[2021-05-04 15:27:39,788: INFO/MainProcess] Received task: create_csv[ee1783bd-bfa5-4c94-a174-8668d07da1f9]  
[2021-05-04 15:27:39,834: ERROR/ForkPoolWorker-4] Task create_csv[ee1783bd-bfa5-4c94-a174-8668d07da1f9] raised unexpected: ProgrammingError('column FakeCsvApp_schemas.ColumnSeparator does not exist\nLINE 1: ..._schemas"."User_id", "FakeCsvApp_schemas"."Name", "FakeCsvAp...\n                                                             ^\n')
Traceback (most recent call last):
  File "/usr/local/lib/python3.7/site-packages/django/db/backends/utils.py", line 84, in _execute
    return self.cursor.execute(sql, params)
psycopg2.errors.UndefinedColumn: column FakeCsvApp_schemas.ColumnSeparator does not exist
LINE 1: ..._schemas"."User_id", "FakeCsvApp_schemas"."Name", "FakeCsvAp...
                                                             ^


The above exception was the direct cause of the following exception:

Traceback (most recent call last):
  File "/usr/local/lib/python3.7/site-packages/celery/app/trace.py", line 405, in trace_task
    R = retval = fun(*args, **kwargs)
  File "/usr/local/lib/python3.7/site-packages/celery/app/trace.py", line 697, in __protected_call__
    return self.run(*args, **kwargs)
  File "/usr/src/app/FakeCsvApp/tasks.py", line 44, in create_csv_task
    column_name, column_type, column_from, column_to, schema_date_modified = prepare_data(schema_id)
  File "/usr/src/app/FakeCsvApp/tasks.py", line 19, in prepare_data
    schema = Schemas.objects.get(id=schema_id)
  File "/usr/local/lib/python3.7/site-packages/django/db/models/manager.py", line 85, in manager_method
    return getattr(self.get_queryset(), name)(*args, **kwargs)
  File "/usr/local/lib/python3.7/site-packages/django/db/models/query.py", line 431, in get
    num = len(clone)
  File "/usr/local/lib/python3.7/site-packages/django/db/models/query.py", line 262, in __len__
    self._fetch_all()
  File "/usr/local/lib/python3.7/site-packages/django/db/models/query.py", line 1324, in _fetch_all
    self._result_cache = list(self._iterable_class(self))
  File "/usr/local/lib/python3.7/site-packages/django/db/models/query.py", line 51, in __iter__
    results = compiler.execute_sql(chunked_fetch=self.chunked_fetch, chunk_size=self.chunk_size)
  File "/usr/local/lib/python3.7/site-packages/django/db/models/sql/compiler.py", line 1169, in execute_sql
    cursor.execute(sql, params)
  File "/usr/local/lib/python3.7/site-packages/django/db/backends/utils.py", line 98, in execute
    return super().execute(sql, params)
  File "/usr/local/lib/python3.7/site-packages/django/db/backends/utils.py", line 66, in execute
    return self._execute_with_wrappers(sql, params, many=False, executor=self._execute)
  File "/usr/local/lib/python3.7/site-packages/django/db/backends/utils.py", line 75, in _execute_with_wrappers
    return executor(sql, params, many, context)
  File "/usr/local/lib/python3.7/site-packages/django/db/backends/utils.py", line 84, in _execute
    return self.cursor.execute(sql, params)
  File "/usr/local/lib/python3.7/site-packages/django/db/utils.py", line 90, in __exit__
    raise dj_exc_value.with_traceback(traceback) from exc_value
  File "/usr/local/lib/python3.7/site-packages/django/db/backends/utils.py", line 84, in _execute
    return self.cursor.execute(sql, params)
django.db.utils.ProgrammingError: column FakeCsvApp_schemas.ColumnSeparator does not exist
LINE 1: ..._schemas"."User_id", "FakeCsvApp_schemas"."Name", "FakeCsvAp...
                                                             ^

[2021-05-04 15:27:57,670: INFO/MainProcess] Received task: create_csv[294700bf-47e5-4273-860d-76c4ee9fb788]  
[2021-05-04 15:27:57,688: ERROR/ForkPoolWorker-4] Task create_csv[294700bf-47e5-4273-860d-76c4ee9fb788] raised unexpected: ProgrammingError('column FakeCsvApp_schemas.ColumnSeparator does not exist\nLINE 1: ..._schemas"."User_id", "FakeCsvApp_schemas"."Name", "FakeCsvAp...\n                                                             ^\n')
Traceback (most recent call last):
  File "/usr/local/lib/python3.7/site-packages/django/db/backends/utils.py", line 84, in _execute
    return self.cursor.execute(sql, params)
psycopg2.errors.UndefinedColumn: column FakeCsvApp_schemas.ColumnSeparator does not exist
LINE 1: ..._schemas"."User_id", "FakeCsvApp_schemas"."Name", "FakeCsvAp...
                                                             ^


The above exception was the direct cause of the following exception:

Traceback (most recent call last):
  File "/usr/local/lib/python3.7/site-packages/celery/app/trace.py", line 405, in trace_task
    R = retval = fun(*args, **kwargs)
  File "/usr/local/lib/python3.7/site-packages/celery/app/trace.py", line 697, in __protected_call__
    return self.run(*args, **kwargs)
  File "/usr/src/app/FakeCsvApp/tasks.py", line 44, in create_csv_task
    column_name, column_type, column_from, column_to, schema_date_modified = prepare_data(schema_id)
  File "/usr/src/app/FakeCsvApp/tasks.py", line 19, in prepare_data
    schema = Schemas.objects.get(id=schema_id)
  File "/usr/local/lib/python3.7/site-packages/django/db/models/manager.py", line 85, in manager_method
    return getattr(self.get_queryset(), name)(*args, **kwargs)
  File "/usr/local/lib/python3.7/site-packages/django/db/models/query.py", line 431, in get
    num = len(clone)
  File "/usr/local/lib/python3.7/site-packages/django/db/models/query.py", line 262, in __len__
    self._fetch_all()
  File "/usr/local/lib/python3.7/site-packages/django/db/models/query.py", line 1324, in _fetch_all
    self._result_cache = list(self._iterable_class(self))
  File "/usr/local/lib/python3.7/site-packages/django/db/models/query.py", line 51, in __iter__
    results = compiler.execute_sql(chunked_fetch=self.chunked_fetch, chunk_size=self.chunk_size)
  File "/usr/local/lib/python3.7/site-packages/django/db/models/sql/compiler.py", line 1169, in execute_sql
    cursor.execute(sql, params)
  File "/usr/local/lib/python3.7/site-packages/django/db/backends/utils.py", line 98, in execute
    return super().execute(sql, params)
  File "/usr/local/lib/python3.7/site-packages/django/db/backends/utils.py", line 66, in execute
    return self._execute_with_wrappers(sql, params, many=False, executor=self._execute)
  File "/usr/local/lib/python3.7/site-packages/django/db/backends/utils.py", line 75, in _execute_with_wrappers
    return executor(sql, params, many, context)
  File "/usr/local/lib/python3.7/site-packages/django/db/backends/utils.py", line 84, in _execute
    return self.cursor.execute(sql, params)
  File "/usr/local/lib/python3.7/site-packages/django/db/utils.py", line 90, in __exit__
    raise dj_exc_value.with_traceback(traceback) from exc_value
  File "/usr/local/lib/python3.7/site-packages/django/db/backends/utils.py", line 84, in _execute
    return self.cursor.execute(sql, params)
django.db.utils.ProgrammingError: column FakeCsvApp_schemas.ColumnSeparator does not exist
LINE 1: ..._schemas"."User_id", "FakeCsvApp_schemas"."Name", "FakeCsvAp...
                                                             ^

[2021-05-04 15:28:12,509: INFO/MainProcess] Received task: create_csv[eb005ce1-db30-43a2-9104-d6d5740859a5]  
[2021-05-04 15:28:12,522: ERROR/ForkPoolWorker-4] Task create_csv[eb005ce1-db30-43a2-9104-d6d5740859a5] raised unexpected: ProgrammingError('column FakeCsvApp_schemas.ColumnSeparator does not exist\nLINE 1: ..._schemas"."User_id", "FakeCsvApp_schemas"."Name", "FakeCsvAp...\n                                                             ^\n')
Traceback (most recent call last):
  File "/usr/local/lib/python3.7/site-packages/django/db/backends/utils.py", line 84, in _execute
    return self.cursor.execute(sql, params)
psycopg2.errors.UndefinedColumn: column FakeCsvApp_schemas.ColumnSeparator does not exist
LINE 1: ..._schemas"."User_id", "FakeCsvApp_schemas"."Name", "FakeCsvAp...
                                                             ^


The above exception was the direct cause of the following exception:

Traceback (most recent call last):
  File "/usr/local/lib/python3.7/site-packages/celery/app/trace.py", line 405, in trace_task
    R = retval = fun(*args, **kwargs)
  File "/usr/local/lib/python3.7/site-packages/celery/app/trace.py", line 697, in __protected_call__
    return self.run(*args, **kwargs)
  File "/usr/src/app/FakeCsvApp/tasks.py", line 44, in create_csv_task
    column_name, column_type, column_from, column_to, schema_date_modified = prepare_data(schema_id)
  File "/usr/src/app/FakeCsvApp/tasks.py", line 19, in prepare_data
    schema = Schemas.objects.get(id=schema_id)
  File "/usr/local/lib/python3.7/site-packages/django/db/models/manager.py", line 85, in manager_method
    return getattr(self.get_queryset(), name)(*args, **kwargs)
  File "/usr/local/lib/python3.7/site-packages/django/db/models/query.py", line 431, in get
    num = len(clone)
  File "/usr/local/lib/python3.7/site-packages/django/db/models/query.py", line 262, in __len__
    self._fetch_all()
  File "/usr/local/lib/python3.7/site-packages/django/db/models/query.py", line 1324, in _fetch_all
    self._result_cache = list(self._iterable_class(self))
  File "/usr/local/lib/python3.7/site-packages/django/db/models/query.py", line 51, in __iter__
    results = compiler.execute_sql(chunked_fetch=self.chunked_fetch, chunk_size=self.chunk_size)
  File "/usr/local/lib/python3.7/site-packages/django/db/models/sql/compiler.py", line 1169, in execute_sql
    cursor.execute(sql, params)
  File "/usr/local/lib/python3.7/site-packages/django/db/backends/utils.py", line 98, in execute
    return super().execute(sql, params)
  File "/usr/local/lib/python3.7/site-packages/django/db/backends/utils.py", line 66, in execute
    return self._execute_with_wrappers(sql, params, many=False, executor=self._execute)
  File "/usr/local/lib/python3.7/site-packages/django/db/backends/utils.py", line 75, in _execute_with_wrappers
    return executor(sql, params, many, context)
  File "/usr/local/lib/python3.7/site-packages/django/db/backends/utils.py", line 84, in _execute
    return self.cursor.execute(sql, params)
  File "/usr/local/lib/python3.7/site-packages/django/db/utils.py", line 90, in __exit__
    raise dj_exc_value.with_traceback(traceback) from exc_value
  File "/usr/local/lib/python3.7/site-packages/django/db/backends/utils.py", line 84, in _execute
    return self.cursor.execute(sql, params)
django.db.utils.ProgrammingError: column FakeCsvApp_schemas.ColumnSeparator does not exist
LINE 1: ..._schemas"."User_id", "FakeCsvApp_schemas"."Name", "FakeCsvAp...
                                                             ^

[2021-05-04 15:30:54,455: INFO/MainProcess] beat: Shutting down...
[2021-05-04 15:31:31,584: INFO/MainProcess] Connected to redis://redis:6379//
[2021-05-04 15:31:31,599: INFO/MainProcess] mingle: searching for neighbors
[2021-05-04 15:31:32,589: INFO/MainProcess] mingle: all alone
[2021-05-04 15:31:32,607: WARNING/MainProcess] /usr/local/lib/python3.7/site-packages/celery/fixups/django.py:204: UserWarning: Using settings.DEBUG leads to a memory
            leak, never use this setting in production environments!
  leak, never use this setting in production environments!''')

[2021-05-04 15:31:32,609: INFO/MainProcess] celery@62b376e97fe9 ready.
[2021-05-04 15:31:33,393: INFO/Beat] beat: Starting...
[2021-05-04 15:31:50,305: INFO/MainProcess] Received task: create_csv[5c3306f9-e3bd-4809-a436-d67cbee0105b]  
[2021-05-04 15:31:50,354: INFO/ForkPoolWorker-4] Task create_csv[5c3306f9-e3bd-4809-a436-d67cbee0105b] succeeded in 0.04365250000046217s: ('1_2021-05-04T15:31:50.328265Z.csv', '2021-05-04T15:31:50.328265Z')
[2021-05-04 15:32:20,869: INFO/MainProcess] Received task: create_csv[a408b65c-32b9-4170-adeb-7cbed7058ae3]  
[2021-05-04 15:32:20,891: INFO/ForkPoolWorker-4] Task create_csv[a408b65c-32b9-4170-adeb-7cbed7058ae3] succeeded in 0.01934739999978774s: ('1_2021-05-04T15:32:20.878277Z.csv', '2021-05-04T15:32:20.878277Z')
[2021-05-04 15:33:22,115: INFO/MainProcess] Received task: create_csv[bfb0d0ef-f2f8-4eb0-b9fe-d56f6502c30e]  
[2021-05-04 15:33:22,140: INFO/ForkPoolWorker-4] Task create_csv[bfb0d0ef-f2f8-4eb0-b9fe-d56f6502c30e] succeeded in 0.02023280000048544s: ('1_2021-05-04T15:33:22.126756Z.csv', '2021-05-04T15:33:22.126756Z')
[2021-05-04 15:35:06,490: INFO/MainProcess] Received task: create_csv[984fd70e-f52c-4088-9df6-7fc2e94c9dbf]  
[2021-05-04 15:35:06,516: INFO/ForkPoolWorker-4] Task create_csv[984fd70e-f52c-4088-9df6-7fc2e94c9dbf] succeeded in 0.020977600000151142s: ('1_2021-05-04T15:35:06.501263Z.csv', '2021-05-04T15:35:06.501263Z')
[2021-05-04 15:37:42,183: INFO/MainProcess] Received task: create_csv[be342d9a-951c-441d-a689-0583a0fb8bdd]  
[2021-05-04 15:37:42,209: INFO/ForkPoolWorker-4] Task create_csv[be342d9a-951c-441d-a689-0583a0fb8bdd] succeeded in 0.022096200000305544s: ('1_2021-05-04T15:37:42.195294Z.csv', '2021-05-04T15:37:42.195294Z')
[2021-05-04 15:39:29,789: INFO/MainProcess] Received task: create_csv[b1d5f69c-3a68-40ff-ad8d-c0fb35be655f]  
[2021-05-04 15:39:29,812: INFO/ForkPoolWorker-4] Task create_csv[b1d5f69c-3a68-40ff-ad8d-c0fb35be655f] succeeded in 0.02063069999894651s: ('1_2021-05-04T15:39:29.799097Z.csv', '2021-05-04T15:39:29.799097Z')
[2021-05-04 15:40:27,242: INFO/MainProcess] Received task: create_csv[956baf2d-7a21-4ada-8ef1-d2319974f73f]  
[2021-05-04 15:40:27,268: INFO/ForkPoolWorker-4] Task create_csv[956baf2d-7a21-4ada-8ef1-d2319974f73f] succeeded in 0.02209740000034799s: ('1_2021-05-04T15:40:27.254127Z.csv', '2021-05-04T15:40:27.254127Z')
[2021-05-04 15:42:19,825: INFO/MainProcess] Received task: create_csv[11b25fab-7f41-4343-b925-b4a29ae75e5b]  
[2021-05-04 15:42:19,851: INFO/ForkPoolWorker-4] Task create_csv[11b25fab-7f41-4343-b925-b4a29ae75e5b] succeeded in 0.02220350000061444s: ('1_2021-05-04T15:42:19.835773Z.csv', '2021-05-04T15:42:19.835773Z')
[2021-05-04 15:48:06,710: INFO/MainProcess] Received task: create_csv[dcb4b39f-a680-4590-9174-a15d34f52bee]  
[2021-05-04 15:48:06,735: INFO/ForkPoolWorker-4] Task create_csv[dcb4b39f-a680-4590-9174-a15d34f52bee] succeeded in 0.02148029999989376s: ('1_2021-05-04T15:48:06.721317Z.csv', '2021-05-04T15:48:06.721317Z')
[2021-05-04 15:50:39,880: INFO/MainProcess] Received task: create_csv[ea91f062-3a16-43e7-a2d0-4383839a48d5]  
[2021-05-04 15:50:39,906: INFO/ForkPoolWorker-4] Task create_csv[ea91f062-3a16-43e7-a2d0-4383839a48d5] succeeded in 0.022642500000074506s: ('1_2021-05-04T15:50:39.890095Z.csv', '2021-05-04T15:50:39.890095Z')
[2021-05-05 03:29:45,769: INFO/MainProcess] beat: Shutting down...
[2021-05-05 03:30:53,153: ERROR/MainProcess] consumer: Cannot connect to redis://redis:6379//: Error 111 connecting to redis:6379. Connection refused..
Trying again in 2.00 seconds... (1/100)

[2021-05-05 03:30:55,308: INFO/Beat] beat: Starting...
[2021-05-05 03:30:55,453: ERROR/MainProcess] consumer: Cannot connect to redis://redis:6379//: Error -2 connecting to redis:6379. Name or service not known..
Trying again in 4.00 seconds... (2/100)

[2021-05-05 03:30:59,481: ERROR/MainProcess] consumer: Cannot connect to redis://redis:6379//: Error -2 connecting to redis:6379. Name or service not known..
Trying again in 6.00 seconds... (3/100)

[2021-05-05 03:31:05,521: ERROR/MainProcess] consumer: Cannot connect to redis://redis:6379//: Error -2 connecting to redis:6379. Name or service not known..
Trying again in 8.00 seconds... (4/100)

[2021-05-05 03:31:13,563: ERROR/MainProcess] consumer: Cannot connect to redis://redis:6379//: Error -2 connecting to redis:6379. Name or service not known..
Trying again in 10.00 seconds... (5/100)

[2021-05-05 03:31:23,559: ERROR/MainProcess] consumer: Cannot connect to redis://redis:6379//: Error -2 connecting to redis:6379. Name or service not known..
Trying again in 12.00 seconds... (6/100)

[2021-05-05 03:31:35,595: ERROR/MainProcess] consumer: Cannot connect to redis://redis:6379//: Error -2 connecting to redis:6379. Name or service not known..
Trying again in 14.00 seconds... (7/100)

[2021-05-05 03:31:49,623: ERROR/MainProcess] consumer: Cannot connect to redis://redis:6379//: Error -2 connecting to redis:6379. Name or service not known..
Trying again in 16.00 seconds... (8/100)

[2021-05-05 03:32:05,616: ERROR/MainProcess] consumer: Cannot connect to redis://redis:6379//: Error -2 connecting to redis:6379. Name or service not known..
Trying again in 18.00 seconds... (9/100)

[2021-05-05 03:32:23,617: ERROR/MainProcess] consumer: Cannot connect to redis://redis:6379//: Error -2 connecting to redis:6379. Name or service not known..
Trying again in 20.00 seconds... (10/100)

[2021-05-05 03:32:43,660: ERROR/MainProcess] consumer: Cannot connect to redis://redis:6379//: Error -2 connecting to redis:6379. Name or service not known..
Trying again in 22.00 seconds... (11/100)

[2021-05-05 03:33:05,664: ERROR/MainProcess] consumer: Cannot connect to redis://redis:6379//: Error -2 connecting to redis:6379. Name or service not known..
Trying again in 24.00 seconds... (12/100)

[2021-05-05 03:33:30,512: ERROR/MainProcess] consumer: Cannot connect to redis://redis:6379//: Error -2 connecting to redis:6379. Name or service not known..
Trying again in 26.00 seconds... (13/100)

[2021-05-05 03:33:56,531: ERROR/MainProcess] consumer: Cannot connect to redis://redis:6379//: Error -2 connecting to redis:6379. Name or service not known..
Trying again in 28.00 seconds... (14/100)

[2021-05-05 03:34:24,545: ERROR/MainProcess] consumer: Cannot connect to redis://redis:6379//: Error -2 connecting to redis:6379. Name or service not known..
Trying again in 30.00 seconds... (15/100)

[2021-05-05 03:34:54,566: ERROR/MainProcess] consumer: Cannot connect to redis://redis:6379//: Error -2 connecting to redis:6379. Name or service not known..
Trying again in 32.00 seconds... (16/100)

[2021-05-05 03:35:26,602: ERROR/MainProcess] consumer: Cannot connect to redis://redis:6379//: Error -2 connecting to redis:6379. Name or service not known..
Trying again in 32.00 seconds... (16/100)

[2021-05-05 03:35:29,927: INFO/MainProcess] beat: Shutting down...
[2021-05-06 16:51:43,686: ERROR/MainProcess] consumer: Cannot connect to redis://:**@ec2-18-213-92-149.compute-1.amazonaws.com:29630//: Connection closed by server..
Trying again in 2.00 seconds... (1/100)

[2021-05-06 16:51:44,809: INFO/Beat] beat: Starting...
[2021-05-06 16:51:46,126: ERROR/MainProcess] consumer: Cannot connect to redis://:**@ec2-18-213-92-149.compute-1.amazonaws.com:29630//: Connection closed by server..
Trying again in 4.00 seconds... (2/100)

[2021-05-06 16:51:50,680: ERROR/MainProcess] consumer: Cannot connect to redis://:**@ec2-18-213-92-149.compute-1.amazonaws.com:29630//: Connection closed by server..
Trying again in 6.00 seconds... (3/100)

[2021-05-06 16:51:56,402: INFO/MainProcess] beat: Shutting down...
[2021-05-06 16:52:16,142: ERROR/MainProcess] consumer: Cannot connect to redis://:**@ec2-18-213-92-149.compute-1.amazonaws.com:29630//: Connection closed by server..
Trying again in 2.00 seconds... (1/100)

[2021-05-06 16:52:17,763: INFO/Beat] beat: Starting...
[2021-05-06 16:52:18,723: ERROR/MainProcess] consumer: Cannot connect to redis://:**@ec2-18-213-92-149.compute-1.amazonaws.com:29630//: Connection closed by server..
Trying again in 4.00 seconds... (2/100)

[2021-05-06 16:52:23,165: ERROR/MainProcess] consumer: Cannot connect to redis://:**@ec2-18-213-92-149.compute-1.amazonaws.com:29630//: Connection closed by server..
Trying again in 6.00 seconds... (3/100)

[2021-05-06 16:52:29,695: ERROR/MainProcess] consumer: Cannot connect to redis://:**@ec2-18-213-92-149.compute-1.amazonaws.com:29630//: Connection closed by server..
Trying again in 8.00 seconds... (4/100)

[2021-05-06 16:52:38,240: ERROR/MainProcess] consumer: Cannot connect to redis://:**@ec2-18-213-92-149.compute-1.amazonaws.com:29630//: Connection closed by server..
Trying again in 10.00 seconds... (5/100)

[2021-05-06 16:52:48,931: ERROR/MainProcess] consumer: Cannot connect to redis://:**@ec2-18-213-92-149.compute-1.amazonaws.com:29630//: Connection closed by server..
Trying again in 12.00 seconds... (6/100)

[2021-05-06 16:53:01,416: ERROR/MainProcess] consumer: Cannot connect to redis://:**@ec2-18-213-92-149.compute-1.amazonaws.com:29630//: Connection closed by server..
Trying again in 14.00 seconds... (7/100)

[2021-05-06 16:53:15,902: ERROR/MainProcess] consumer: Cannot connect to redis://:**@ec2-18-213-92-149.compute-1.amazonaws.com:29630//: Connection closed by server..
Trying again in 16.00 seconds... (8/100)

[2021-05-06 16:53:32,534: ERROR/MainProcess] consumer: Cannot connect to redis://:**@ec2-18-213-92-149.compute-1.amazonaws.com:29630//: Connection closed by server..
Trying again in 18.00 seconds... (9/100)

[2021-05-06 16:53:51,121: ERROR/MainProcess] consumer: Cannot connect to redis://:**@ec2-18-213-92-149.compute-1.amazonaws.com:29630//: Connection closed by server..
Trying again in 20.00 seconds... (10/100)

[2021-05-06 16:54:11,627: ERROR/MainProcess] consumer: Cannot connect to redis://:**@ec2-18-213-92-149.compute-1.amazonaws.com:29630//: Connection closed by server..
Trying again in 22.00 seconds... (11/100)

[2021-05-06 16:54:34,189: ERROR/MainProcess] consumer: Cannot connect to redis://:**@ec2-18-213-92-149.compute-1.amazonaws.com:29630//: Connection closed by server..
Trying again in 24.00 seconds... (12/100)

[2021-05-06 16:54:58,692: ERROR/MainProcess] consumer: Cannot connect to redis://:**@ec2-18-213-92-149.compute-1.amazonaws.com:29630//: Connection closed by server..
Trying again in 26.00 seconds... (13/100)

[2021-05-06 16:55:25,420: ERROR/MainProcess] consumer: Cannot connect to redis://:**@ec2-18-213-92-149.compute-1.amazonaws.com:29630//: Connection closed by server..
Trying again in 28.00 seconds... (14/100)

[2021-05-06 16:55:54,077: ERROR/MainProcess] consumer: Cannot connect to redis://:**@ec2-18-213-92-149.compute-1.amazonaws.com:29630//: Connection closed by server..
Trying again in 30.00 seconds... (15/100)

[2021-05-06 16:56:24,607: ERROR/MainProcess] consumer: Cannot connect to redis://:**@ec2-18-213-92-149.compute-1.amazonaws.com:29630//: Connection closed by server..
Trying again in 32.00 seconds... (16/100)

[2021-05-06 16:56:57,166: ERROR/MainProcess] consumer: Cannot connect to redis://:**@ec2-18-213-92-149.compute-1.amazonaws.com:29630//: Connection closed by server..
Trying again in 32.00 seconds... (16/100)

[2021-05-06 16:57:29,736: ERROR/MainProcess] consumer: Cannot connect to redis://:**@ec2-18-213-92-149.compute-1.amazonaws.com:29630//: Connection closed by server..
Trying again in 32.00 seconds... (16/100)

[2021-05-06 16:58:04,870: ERROR/MainProcess] consumer: Cannot connect to redis://:**@ec2-18-213-92-149.compute-1.amazonaws.com:29630//: Connection closed by server..
Trying again in 32.00 seconds... (16/100)

[2021-05-06 16:58:37,924: ERROR/MainProcess] consumer: Cannot connect to redis://:**@ec2-18-213-92-149.compute-1.amazonaws.com:29630//: Connection closed by server..
Trying again in 32.00 seconds... (16/100)

[2021-05-06 16:59:10,398: ERROR/MainProcess] consumer: Cannot connect to redis://:**@ec2-18-213-92-149.compute-1.amazonaws.com:29630//: Connection closed by server..
Trying again in 32.00 seconds... (16/100)

[2021-05-06 16:59:36,640: INFO/MainProcess] beat: Shutting down...
